[2025-04-20T02:03:31.198+0000] {taskinstance.py:1157} INFO - Dependencies all met for dep_context=non-requeueable deps ti=<TaskInstance: spacex_ml_training_pipeline.train_model manual__2025-04-20T02:03:30.213029+00:00 [queued]>
[2025-04-20T02:03:31.203+0000] {taskinstance.py:1157} INFO - Dependencies all met for dep_context=requeueable deps ti=<TaskInstance: spacex_ml_training_pipeline.train_model manual__2025-04-20T02:03:30.213029+00:00 [queued]>
[2025-04-20T02:03:31.203+0000] {taskinstance.py:1359} INFO - Starting attempt 1 of 2
[2025-04-20T02:03:31.210+0000] {taskinstance.py:1380} INFO - Executing <Task(BashOperator): train_model> on 2025-04-20 02:03:30.213029+00:00
[2025-04-20T02:03:31.213+0000] {standard_task_runner.py:57} INFO - Started process 206 to run task
[2025-04-20T02:03:31.217+0000] {standard_task_runner.py:84} INFO - Running: ['***', 'tasks', 'run', 'spacex_ml_training_pipeline', 'train_model', 'manual__2025-04-20T02:03:30.213029+00:00', '--job-id', '3', '--raw', '--subdir', 'DAGS_FOLDER/spacex_training_dag.py', '--cfg-path', '/tmp/tmpiuswbwr8']
[2025-04-20T02:03:31.219+0000] {standard_task_runner.py:85} INFO - Job 3: Subtask train_model
[2025-04-20T02:03:31.230+0000] {logging_mixin.py:151} WARNING - /home/***/.local/lib/python3.8/site-packages/***/settings.py:195 DeprecationWarning: The sql_alchemy_conn option in [core] has been moved to the sql_alchemy_conn option in [database] - the old setting has been used, but please update your config.
[2025-04-20T02:03:31.255+0000] {task_command.py:415} INFO - Running <TaskInstance: spacex_ml_training_pipeline.train_model manual__2025-04-20T02:03:30.213029+00:00 [running]> on host fd4505c3894d
[2025-04-20T02:03:31.297+0000] {taskinstance.py:1660} INFO - Exporting env vars: AIRFLOW_CTX_DAG_OWNER='gaurav' AIRFLOW_CTX_DAG_ID='spacex_ml_training_pipeline' AIRFLOW_CTX_TASK_ID='train_model' AIRFLOW_CTX_EXECUTION_DATE='2025-04-20T02:03:30.213029+00:00' AIRFLOW_CTX_TRY_NUMBER='1' AIRFLOW_CTX_DAG_RUN_ID='manual__2025-04-20T02:03:30.213029+00:00'
[2025-04-20T02:03:31.298+0000] {subprocess.py:63} INFO - Tmp dir root location: /tmp
[2025-04-20T02:03:31.299+0000] {subprocess.py:75} INFO - Running command: ['/bin/bash', '-c', 'python /opt/***/project/train.py']
[2025-04-20T02:03:31.304+0000] {subprocess.py:86} INFO - Output:
[2025-04-20T02:03:31.373+0000] {subprocess.py:93} INFO - python: can't open file '/opt/***/project/train.py': [Errno 2] No such file or directory
[2025-04-20T02:03:31.375+0000] {subprocess.py:97} INFO - Command exited with return code 2
[2025-04-20T02:03:31.383+0000] {taskinstance.py:1935} ERROR - Task failed with exception
Traceback (most recent call last):
  File "/home/airflow/.local/lib/python3.8/site-packages/airflow/operators/bash.py", line 210, in execute
    raise AirflowException(
airflow.exceptions.AirflowException: Bash command failed. The command returned a non-zero exit code 2.
[2025-04-20T02:03:31.385+0000] {taskinstance.py:1398} INFO - Marking task as UP_FOR_RETRY. dag_id=spacex_ml_training_pipeline, task_id=train_model, execution_date=20250420T020330, start_date=20250420T020331, end_date=20250420T020331
[2025-04-20T02:03:31.392+0000] {standard_task_runner.py:104} ERROR - Failed to execute job 3 for task train_model (Bash command failed. The command returned a non-zero exit code 2.; 206)
[2025-04-20T02:03:31.400+0000] {local_task_job_runner.py:228} INFO - Task exited with return code 1
[2025-04-20T02:03:31.411+0000] {taskinstance.py:2776} INFO - 0 downstream tasks scheduled from follow-on schedule check
