[2025-04-20T02:08:17.534+0000] {taskinstance.py:1157} INFO - Dependencies all met for dep_context=non-requeueable deps ti=<TaskInstance: spacex_ml_training_pipeline.train_model scheduled__2025-04-13T00:00:00+00:00 [queued]>
[2025-04-20T02:08:17.539+0000] {taskinstance.py:1157} INFO - Dependencies all met for dep_context=requeueable deps ti=<TaskInstance: spacex_ml_training_pipeline.train_model scheduled__2025-04-13T00:00:00+00:00 [queued]>
[2025-04-20T02:08:17.539+0000] {taskinstance.py:1359} INFO - Starting attempt 2 of 2
[2025-04-20T02:08:17.546+0000] {taskinstance.py:1380} INFO - Executing <Task(BashOperator): train_model> on 2025-04-13 00:00:00+00:00
[2025-04-20T02:08:17.550+0000] {standard_task_runner.py:57} INFO - Started process 254 to run task
[2025-04-20T02:08:17.552+0000] {standard_task_runner.py:84} INFO - Running: ['***', 'tasks', 'run', 'spacex_ml_training_pipeline', 'train_model', 'scheduled__2025-04-13T00:00:00+00:00', '--job-id', '4', '--raw', '--subdir', 'DAGS_FOLDER/spacex_training_dag.py', '--cfg-path', '/tmp/tmp5fqgwxm1']
[2025-04-20T02:08:17.554+0000] {standard_task_runner.py:85} INFO - Job 4: Subtask train_model
[2025-04-20T02:08:17.564+0000] {logging_mixin.py:151} WARNING - /home/***/.local/lib/python3.8/site-packages/***/settings.py:195 DeprecationWarning: The sql_alchemy_conn option in [core] has been moved to the sql_alchemy_conn option in [database] - the old setting has been used, but please update your config.
[2025-04-20T02:08:17.589+0000] {task_command.py:415} INFO - Running <TaskInstance: spacex_ml_training_pipeline.train_model scheduled__2025-04-13T00:00:00+00:00 [running]> on host fd4505c3894d
[2025-04-20T02:08:17.635+0000] {taskinstance.py:1660} INFO - Exporting env vars: AIRFLOW_CTX_DAG_OWNER='gaurav' AIRFLOW_CTX_DAG_ID='spacex_ml_training_pipeline' AIRFLOW_CTX_TASK_ID='train_model' AIRFLOW_CTX_EXECUTION_DATE='2025-04-13T00:00:00+00:00' AIRFLOW_CTX_TRY_NUMBER='2' AIRFLOW_CTX_DAG_RUN_ID='scheduled__2025-04-13T00:00:00+00:00'
[2025-04-20T02:08:17.636+0000] {subprocess.py:63} INFO - Tmp dir root location: /tmp
[2025-04-20T02:08:17.637+0000] {subprocess.py:75} INFO - Running command: ['/bin/bash', '-c', 'python /opt/***/project/train.py']
[2025-04-20T02:08:17.642+0000] {subprocess.py:86} INFO - Output:
[2025-04-20T02:08:17.724+0000] {subprocess.py:93} INFO - python: can't open file '/opt/***/project/train.py': [Errno 2] No such file or directory
[2025-04-20T02:08:17.726+0000] {subprocess.py:97} INFO - Command exited with return code 2
[2025-04-20T02:08:17.734+0000] {taskinstance.py:1935} ERROR - Task failed with exception
Traceback (most recent call last):
  File "/home/airflow/.local/lib/python3.8/site-packages/airflow/operators/bash.py", line 210, in execute
    raise AirflowException(
airflow.exceptions.AirflowException: Bash command failed. The command returned a non-zero exit code 2.
[2025-04-20T02:08:17.737+0000] {taskinstance.py:1398} INFO - Marking task as FAILED. dag_id=spacex_ml_training_pipeline, task_id=train_model, execution_date=20250413T000000, start_date=20250420T020817, end_date=20250420T020817
[2025-04-20T02:08:17.745+0000] {standard_task_runner.py:104} ERROR - Failed to execute job 4 for task train_model (Bash command failed. The command returned a non-zero exit code 2.; 254)
[2025-04-20T02:08:17.787+0000] {local_task_job_runner.py:228} INFO - Task exited with return code 1
[2025-04-20T02:08:17.797+0000] {taskinstance.py:2776} INFO - 0 downstream tasks scheduled from follow-on schedule check
[2025-04-20T02:39:25.401+0000] {taskinstance.py:1157} INFO - Dependencies all met for dep_context=non-requeueable deps ti=<TaskInstance: spacex_ml_training_pipeline.train_model scheduled__2025-04-13T00:00:00+00:00 [queued]>
[2025-04-20T02:39:25.406+0000] {taskinstance.py:1157} INFO - Dependencies all met for dep_context=requeueable deps ti=<TaskInstance: spacex_ml_training_pipeline.train_model scheduled__2025-04-13T00:00:00+00:00 [queued]>
[2025-04-20T02:39:25.406+0000] {taskinstance.py:1359} INFO - Starting attempt 2 of 2
[2025-04-20T02:39:25.414+0000] {taskinstance.py:1380} INFO - Executing <Task(BashOperator): train_model> on 2025-04-13 00:00:00+00:00
[2025-04-20T02:39:25.418+0000] {standard_task_runner.py:57} INFO - Started process 251 to run task
[2025-04-20T02:39:25.420+0000] {standard_task_runner.py:84} INFO - Running: ['***', 'tasks', 'run', 'spacex_ml_training_pipeline', 'train_model', 'scheduled__2025-04-13T00:00:00+00:00', '--job-id', '4', '--raw', '--subdir', 'DAGS_FOLDER/spacex_training_dag.py', '--cfg-path', '/tmp/tmplonesm4p']
[2025-04-20T02:39:25.423+0000] {standard_task_runner.py:85} INFO - Job 4: Subtask train_model
[2025-04-20T02:39:25.437+0000] {logging_mixin.py:151} WARNING - /home/***/.local/lib/python3.8/site-packages/***/settings.py:195 DeprecationWarning: The sql_alchemy_conn option in [core] has been moved to the sql_alchemy_conn option in [database] - the old setting has been used, but please update your config.
[2025-04-20T02:39:25.466+0000] {task_command.py:415} INFO - Running <TaskInstance: spacex_ml_training_pipeline.train_model scheduled__2025-04-13T00:00:00+00:00 [running]> on host 7d5e8b868ff6
[2025-04-20T02:39:25.525+0000] {taskinstance.py:1660} INFO - Exporting env vars: AIRFLOW_CTX_DAG_OWNER='gaurav' AIRFLOW_CTX_DAG_ID='spacex_ml_training_pipeline' AIRFLOW_CTX_TASK_ID='train_model' AIRFLOW_CTX_EXECUTION_DATE='2025-04-13T00:00:00+00:00' AIRFLOW_CTX_TRY_NUMBER='2' AIRFLOW_CTX_DAG_RUN_ID='scheduled__2025-04-13T00:00:00+00:00'
[2025-04-20T02:39:25.526+0000] {subprocess.py:63} INFO - Tmp dir root location: /tmp
[2025-04-20T02:39:25.527+0000] {subprocess.py:75} INFO - Running command: ['/bin/bash', '-c', 'python /opt/***/project/train.py']
[2025-04-20T02:39:25.534+0000] {subprocess.py:86} INFO - Output:
[2025-04-20T02:39:26.208+0000] {subprocess.py:93} INFO - Traceback (most recent call last):
[2025-04-20T02:39:26.213+0000] {subprocess.py:93} INFO -   File "/opt/***/project/train.py", line 3, in <module>
[2025-04-20T02:39:26.216+0000] {subprocess.py:93} INFO -     from sklearn import preprocessing
[2025-04-20T02:39:26.216+0000] {subprocess.py:93} INFO - ModuleNotFoundError: No module named 'sklearn'
[2025-04-20T02:39:26.247+0000] {subprocess.py:97} INFO - Command exited with return code 1
[2025-04-20T02:39:26.255+0000] {taskinstance.py:1935} ERROR - Task failed with exception
Traceback (most recent call last):
  File "/home/airflow/.local/lib/python3.8/site-packages/airflow/operators/bash.py", line 210, in execute
    raise AirflowException(
airflow.exceptions.AirflowException: Bash command failed. The command returned a non-zero exit code 1.
[2025-04-20T02:39:26.258+0000] {taskinstance.py:1398} INFO - Marking task as FAILED. dag_id=spacex_ml_training_pipeline, task_id=train_model, execution_date=20250413T000000, start_date=20250420T023925, end_date=20250420T023926
[2025-04-20T02:39:26.266+0000] {standard_task_runner.py:104} ERROR - Failed to execute job 4 for task train_model (Bash command failed. The command returned a non-zero exit code 1.; 251)
[2025-04-20T02:39:26.290+0000] {local_task_job_runner.py:228} INFO - Task exited with return code 1
[2025-04-20T02:39:26.301+0000] {taskinstance.py:2776} INFO - 0 downstream tasks scheduled from follow-on schedule check
[2025-04-20T04:43:14.611+0000] {taskinstance.py:1157} INFO - Dependencies all met for dep_context=non-requeueable deps ti=<TaskInstance: spacex_ml_training_pipeline.train_model scheduled__2025-04-13T00:00:00+00:00 [queued]>
[2025-04-20T04:43:14.615+0000] {taskinstance.py:1157} INFO - Dependencies all met for dep_context=requeueable deps ti=<TaskInstance: spacex_ml_training_pipeline.train_model scheduled__2025-04-13T00:00:00+00:00 [queued]>
[2025-04-20T04:43:14.616+0000] {taskinstance.py:1359} INFO - Starting attempt 2 of 2
[2025-04-20T04:43:14.622+0000] {taskinstance.py:1380} INFO - Executing <Task(BashOperator): train_model> on 2025-04-13 00:00:00+00:00
[2025-04-20T04:43:14.626+0000] {standard_task_runner.py:57} INFO - Started process 321 to run task
[2025-04-20T04:43:14.629+0000] {standard_task_runner.py:84} INFO - Running: ['***', 'tasks', 'run', 'spacex_ml_training_pipeline', 'train_model', 'scheduled__2025-04-13T00:00:00+00:00', '--job-id', '4', '--raw', '--subdir', 'DAGS_FOLDER/spacex_training_dag.py', '--cfg-path', '/tmp/tmpa1k8v3ud']
[2025-04-20T04:43:14.632+0000] {standard_task_runner.py:85} INFO - Job 4: Subtask train_model
[2025-04-20T04:43:14.642+0000] {logging_mixin.py:151} WARNING - /home/***/.local/lib/python3.8/site-packages/***/settings.py:195 DeprecationWarning: The sql_alchemy_conn option in [core] has been moved to the sql_alchemy_conn option in [database] - the old setting has been used, but please update your config.
[2025-04-20T04:43:14.666+0000] {task_command.py:415} INFO - Running <TaskInstance: spacex_ml_training_pipeline.train_model scheduled__2025-04-13T00:00:00+00:00 [running]> on host 86d980d5f4b3
[2025-04-20T04:43:14.709+0000] {taskinstance.py:1660} INFO - Exporting env vars: AIRFLOW_CTX_DAG_OWNER='gaurav' AIRFLOW_CTX_DAG_ID='spacex_ml_training_pipeline' AIRFLOW_CTX_TASK_ID='train_model' AIRFLOW_CTX_EXECUTION_DATE='2025-04-13T00:00:00+00:00' AIRFLOW_CTX_TRY_NUMBER='2' AIRFLOW_CTX_DAG_RUN_ID='scheduled__2025-04-13T00:00:00+00:00'
[2025-04-20T04:43:14.710+0000] {subprocess.py:63} INFO - Tmp dir root location: /tmp
[2025-04-20T04:43:14.711+0000] {subprocess.py:75} INFO - Running command: ['/bin/bash', '-c', 'python /opt/***/project/train.py']
[2025-04-20T04:43:14.717+0000] {subprocess.py:86} INFO - Output:
[2025-04-20T04:43:17.435+0000] {subprocess.py:93} INFO - 2025/04/20 04:43:17 WARNING mlflow.utils.git_utils: Failed to import Git (the Git executable is probably not on your PATH), so Git SHA is not available. Error: Failed to initialize: Bad git executable.
[2025-04-20T04:43:17.436+0000] {subprocess.py:93} INFO - The git executable must be specified in one of the following ways:
[2025-04-20T04:43:17.436+0000] {subprocess.py:93} INFO -     - be included in your $PATH
[2025-04-20T04:43:17.436+0000] {subprocess.py:93} INFO -     - be set via $GIT_PYTHON_GIT_EXECUTABLE
[2025-04-20T04:43:17.437+0000] {subprocess.py:93} INFO -     - explicitly set via git.refresh(<full-path-to-git-executable>)
[2025-04-20T04:43:17.437+0000] {subprocess.py:93} INFO - 
[2025-04-20T04:43:17.437+0000] {subprocess.py:93} INFO - All git commands will error until this is rectified.
[2025-04-20T04:43:17.437+0000] {subprocess.py:93} INFO - 
[2025-04-20T04:43:17.437+0000] {subprocess.py:93} INFO - This initial message can be silenced or aggravated in the future by setting the
[2025-04-20T04:43:17.437+0000] {subprocess.py:93} INFO - $GIT_PYTHON_REFRESH environment variable. Use one of the following values:
[2025-04-20T04:43:17.438+0000] {subprocess.py:93} INFO -     - quiet|q|silence|s|silent|none|n|0: for no message or exception
[2025-04-20T04:43:17.438+0000] {subprocess.py:93} INFO -     - warn|w|warning|log|l|1: for a warning message (logging level CRITICAL, displayed by default)
[2025-04-20T04:43:17.438+0000] {subprocess.py:93} INFO -     - error|e|exception|raise|r|2: for a raised exception
[2025-04-20T04:43:17.438+0000] {subprocess.py:93} INFO - 
[2025-04-20T04:43:17.438+0000] {subprocess.py:93} INFO - Example:
[2025-04-20T04:43:17.439+0000] {subprocess.py:93} INFO -     export GIT_PYTHON_REFRESH=quiet
[2025-04-20T04:43:17.439+0000] {subprocess.py:93} INFO - 
[2025-04-20T04:43:19.420+0000] {subprocess.py:93} INFO - 2025/04/20 04:43:19 WARNING mlflow.models.model: Model logged without a signature and input example. Please set `input_example` parameter when logging the model to auto infer the model signature.
[2025-04-20T04:43:19.433+0000] {subprocess.py:93} INFO - Training LogisticRegression...
[2025-04-20T04:43:19.438+0000] {subprocess.py:93} INFO - Traceback (most recent call last):
[2025-04-20T04:43:19.442+0000] {subprocess.py:93} INFO -   File "/opt/***/project/train.py", line 63, in <module>
[2025-04-20T04:43:19.442+0000] {subprocess.py:93} INFO -     mlflow.sklearn.log_model(clf.best_estimator_, "model")
[2025-04-20T04:43:19.442+0000] {subprocess.py:93} INFO -   File "/home/***/.local/lib/python3.8/site-packages/mlflow/sklearn/__init__.py", line 413, in log_model
[2025-04-20T04:43:19.442+0000] {subprocess.py:93} INFO -     return Model.log(
[2025-04-20T04:43:19.442+0000] {subprocess.py:93} INFO -   File "/home/***/.local/lib/python3.8/site-packages/mlflow/models/model.py", line 744, in log
[2025-04-20T04:43:19.442+0000] {subprocess.py:93} INFO -     mlflow.tracking.fluent.log_artifacts(local_path, mlflow_model.artifact_path, run_id)
[2025-04-20T04:43:19.442+0000] {subprocess.py:93} INFO -   File "/home/***/.local/lib/python3.8/site-packages/mlflow/tracking/fluent.py", line 1170, in log_artifacts
[2025-04-20T04:43:19.443+0000] {subprocess.py:93} INFO -     MlflowClient().log_artifacts(run_id, local_dir, artifact_path)
[2025-04-20T04:43:19.443+0000] {subprocess.py:93} INFO -   File "/home/***/.local/lib/python3.8/site-packages/mlflow/tracking/client.py", line 1977, in log_artifacts
[2025-04-20T04:43:19.443+0000] {subprocess.py:93} INFO -     self._tracking_client.log_artifacts(run_id, local_dir, artifact_path)
[2025-04-20T04:43:19.443+0000] {subprocess.py:93} INFO -   File "/home/***/.local/lib/python3.8/site-packages/mlflow/tracking/_tracking_service/client.py", line 874, in log_artifacts
[2025-04-20T04:43:19.443+0000] {subprocess.py:93} INFO -     self._get_artifact_repo(run_id).log_artifacts(local_dir, artifact_path)
[2025-04-20T04:43:19.443+0000] {subprocess.py:93} INFO -   File "/home/***/.local/lib/python3.8/site-packages/mlflow/store/artifact/local_artifact_repo.py", line 66, in log_artifacts
[2025-04-20T04:43:19.443+0000] {subprocess.py:93} INFO -     mkdir(artifact_dir)
[2025-04-20T04:43:19.443+0000] {subprocess.py:93} INFO -   File "/home/***/.local/lib/python3.8/site-packages/mlflow/utils/file_utils.py", line 211, in mkdir
[2025-04-20T04:43:19.444+0000] {subprocess.py:93} INFO -     raise e
[2025-04-20T04:43:19.444+0000] {subprocess.py:93} INFO -   File "/home/***/.local/lib/python3.8/site-packages/mlflow/utils/file_utils.py", line 208, in mkdir
[2025-04-20T04:43:19.444+0000] {subprocess.py:93} INFO -     os.makedirs(target, exist_ok=True)
[2025-04-20T04:43:19.444+0000] {subprocess.py:93} INFO -   File "/usr/local/lib/python3.8/os.py", line 213, in makedirs
[2025-04-20T04:43:19.444+0000] {subprocess.py:93} INFO -     makedirs(head, exist_ok=exist_ok)
[2025-04-20T04:43:19.444+0000] {subprocess.py:93} INFO -   File "/usr/local/lib/python3.8/os.py", line 213, in makedirs
[2025-04-20T04:43:19.444+0000] {subprocess.py:93} INFO -     makedirs(head, exist_ok=exist_ok)
[2025-04-20T04:43:19.444+0000] {subprocess.py:93} INFO -   File "/usr/local/lib/python3.8/os.py", line 213, in makedirs
[2025-04-20T04:43:19.444+0000] {subprocess.py:93} INFO -     makedirs(head, exist_ok=exist_ok)
[2025-04-20T04:43:19.444+0000] {subprocess.py:93} INFO -   [Previous line repeated 5 more times]
[2025-04-20T04:43:19.444+0000] {subprocess.py:93} INFO -   File "/usr/local/lib/python3.8/os.py", line 223, in makedirs
[2025-04-20T04:43:19.444+0000] {subprocess.py:93} INFO -     mkdir(name, mode)
[2025-04-20T04:43:19.445+0000] {subprocess.py:93} INFO - PermissionError: [Errno 13] Permission denied: '/Users'
[2025-04-20T04:43:19.672+0000] {subprocess.py:97} INFO - Command exited with return code 1
[2025-04-20T04:43:19.680+0000] {taskinstance.py:1935} ERROR - Task failed with exception
Traceback (most recent call last):
  File "/home/airflow/.local/lib/python3.8/site-packages/airflow/operators/bash.py", line 210, in execute
    raise AirflowException(
airflow.exceptions.AirflowException: Bash command failed. The command returned a non-zero exit code 1.
[2025-04-20T04:43:19.682+0000] {taskinstance.py:1398} INFO - Marking task as FAILED. dag_id=spacex_ml_training_pipeline, task_id=train_model, execution_date=20250413T000000, start_date=20250420T044314, end_date=20250420T044319
[2025-04-20T04:43:19.690+0000] {standard_task_runner.py:104} ERROR - Failed to execute job 4 for task train_model (Bash command failed. The command returned a non-zero exit code 1.; 321)
[2025-04-20T04:43:19.697+0000] {local_task_job_runner.py:228} INFO - Task exited with return code 1
[2025-04-20T04:43:19.705+0000] {taskinstance.py:2776} INFO - 0 downstream tasks scheduled from follow-on schedule check
[2025-04-20T05:03:01.743+0000] {taskinstance.py:1157} INFO - Dependencies all met for dep_context=non-requeueable deps ti=<TaskInstance: spacex_ml_training_pipeline.train_model scheduled__2025-04-13T00:00:00+00:00 [queued]>
[2025-04-20T05:03:01.748+0000] {taskinstance.py:1157} INFO - Dependencies all met for dep_context=requeueable deps ti=<TaskInstance: spacex_ml_training_pipeline.train_model scheduled__2025-04-13T00:00:00+00:00 [queued]>
[2025-04-20T05:03:01.748+0000] {taskinstance.py:1359} INFO - Starting attempt 2 of 2
[2025-04-20T05:03:01.755+0000] {taskinstance.py:1380} INFO - Executing <Task(BashOperator): train_model> on 2025-04-13 00:00:00+00:00
[2025-04-20T05:03:01.759+0000] {standard_task_runner.py:57} INFO - Started process 316 to run task
[2025-04-20T05:03:01.762+0000] {standard_task_runner.py:84} INFO - Running: ['***', 'tasks', 'run', 'spacex_ml_training_pipeline', 'train_model', 'scheduled__2025-04-13T00:00:00+00:00', '--job-id', '4', '--raw', '--subdir', 'DAGS_FOLDER/spacex_training_dag.py', '--cfg-path', '/tmp/tmpe0keusbz']
[2025-04-20T05:03:01.763+0000] {standard_task_runner.py:85} INFO - Job 4: Subtask train_model
[2025-04-20T05:03:01.776+0000] {logging_mixin.py:151} WARNING - /home/***/.local/lib/python3.8/site-packages/***/settings.py:195 DeprecationWarning: The sql_alchemy_conn option in [core] has been moved to the sql_alchemy_conn option in [database] - the old setting has been used, but please update your config.
[2025-04-20T05:03:01.805+0000] {task_command.py:415} INFO - Running <TaskInstance: spacex_ml_training_pipeline.train_model scheduled__2025-04-13T00:00:00+00:00 [running]> on host 8fb4bd7cdd4c
[2025-04-20T05:03:01.858+0000] {taskinstance.py:1660} INFO - Exporting env vars: AIRFLOW_CTX_DAG_OWNER='gaurav' AIRFLOW_CTX_DAG_ID='spacex_ml_training_pipeline' AIRFLOW_CTX_TASK_ID='train_model' AIRFLOW_CTX_EXECUTION_DATE='2025-04-13T00:00:00+00:00' AIRFLOW_CTX_TRY_NUMBER='2' AIRFLOW_CTX_DAG_RUN_ID='scheduled__2025-04-13T00:00:00+00:00'
[2025-04-20T05:03:01.859+0000] {subprocess.py:63} INFO - Tmp dir root location: /tmp
[2025-04-20T05:03:01.860+0000] {subprocess.py:75} INFO - Running command: ['/bin/bash', '-c', 'python /opt/***/project/train.py']
[2025-04-20T05:03:01.866+0000] {subprocess.py:86} INFO - Output:
[2025-04-20T05:03:04.140+0000] {subprocess.py:93} INFO - 2025/04/20 05:03:04 WARNING mlflow.utils.git_utils: Failed to import Git (the Git executable is probably not on your PATH), so Git SHA is not available. Error: Failed to initialize: Bad git executable.
[2025-04-20T05:03:04.141+0000] {subprocess.py:93} INFO - The git executable must be specified in one of the following ways:
[2025-04-20T05:03:04.141+0000] {subprocess.py:93} INFO -     - be included in your $PATH
[2025-04-20T05:03:04.141+0000] {subprocess.py:93} INFO -     - be set via $GIT_PYTHON_GIT_EXECUTABLE
[2025-04-20T05:03:04.141+0000] {subprocess.py:93} INFO -     - explicitly set via git.refresh(<full-path-to-git-executable>)
[2025-04-20T05:03:04.141+0000] {subprocess.py:93} INFO - 
[2025-04-20T05:03:04.142+0000] {subprocess.py:93} INFO - All git commands will error until this is rectified.
[2025-04-20T05:03:04.142+0000] {subprocess.py:93} INFO - 
[2025-04-20T05:03:04.142+0000] {subprocess.py:93} INFO - This initial message can be silenced or aggravated in the future by setting the
[2025-04-20T05:03:04.142+0000] {subprocess.py:93} INFO - $GIT_PYTHON_REFRESH environment variable. Use one of the following values:
[2025-04-20T05:03:04.142+0000] {subprocess.py:93} INFO -     - quiet|q|silence|s|silent|none|n|0: for no message or exception
[2025-04-20T05:03:04.142+0000] {subprocess.py:93} INFO -     - warn|w|warning|log|l|1: for a warning message (logging level CRITICAL, displayed by default)
[2025-04-20T05:03:04.143+0000] {subprocess.py:93} INFO -     - error|e|exception|raise|r|2: for a raised exception
[2025-04-20T05:03:04.143+0000] {subprocess.py:93} INFO - 
[2025-04-20T05:03:04.143+0000] {subprocess.py:93} INFO - Example:
[2025-04-20T05:03:04.143+0000] {subprocess.py:93} INFO -     export GIT_PYTHON_REFRESH=quiet
[2025-04-20T05:03:04.143+0000] {subprocess.py:93} INFO - 
[2025-04-20T05:03:06.170+0000] {subprocess.py:93} INFO - 2025/04/20 05:03:06 WARNING mlflow.models.model: Model logged without a signature and input example. Please set `input_example` parameter when logging the model to auto infer the model signature.
[2025-04-20T05:03:06.186+0000] {subprocess.py:93} INFO - Training LogisticRegression...
[2025-04-20T05:03:06.188+0000] {subprocess.py:93} INFO - Traceback (most recent call last):
[2025-04-20T05:03:06.188+0000] {subprocess.py:93} INFO -   File "/opt/***/project/train.py", line 63, in <module>
[2025-04-20T05:03:06.188+0000] {subprocess.py:93} INFO -     mlflow.sklearn.log_model(clf.best_estimator_, "model")
[2025-04-20T05:03:06.189+0000] {subprocess.py:93} INFO -   File "/home/***/.local/lib/python3.8/site-packages/mlflow/sklearn/__init__.py", line 413, in log_model
[2025-04-20T05:03:06.189+0000] {subprocess.py:93} INFO -     return Model.log(
[2025-04-20T05:03:06.189+0000] {subprocess.py:93} INFO -   File "/home/***/.local/lib/python3.8/site-packages/mlflow/models/model.py", line 744, in log
[2025-04-20T05:03:06.189+0000] {subprocess.py:93} INFO -     mlflow.tracking.fluent.log_artifacts(local_path, mlflow_model.artifact_path, run_id)
[2025-04-20T05:03:06.189+0000] {subprocess.py:93} INFO -   File "/home/***/.local/lib/python3.8/site-packages/mlflow/tracking/fluent.py", line 1170, in log_artifacts
[2025-04-20T05:03:06.189+0000] {subprocess.py:93} INFO -     MlflowClient().log_artifacts(run_id, local_dir, artifact_path)
[2025-04-20T05:03:06.189+0000] {subprocess.py:93} INFO -   File "/home/***/.local/lib/python3.8/site-packages/mlflow/tracking/client.py", line 1977, in log_artifacts
[2025-04-20T05:03:06.189+0000] {subprocess.py:93} INFO -     self._tracking_client.log_artifacts(run_id, local_dir, artifact_path)
[2025-04-20T05:03:06.190+0000] {subprocess.py:93} INFO -   File "/home/***/.local/lib/python3.8/site-packages/mlflow/tracking/_tracking_service/client.py", line 874, in log_artifacts
[2025-04-20T05:03:06.190+0000] {subprocess.py:93} INFO -     self._get_artifact_repo(run_id).log_artifacts(local_dir, artifact_path)
[2025-04-20T05:03:06.190+0000] {subprocess.py:93} INFO -   File "/home/***/.local/lib/python3.8/site-packages/mlflow/store/artifact/local_artifact_repo.py", line 66, in log_artifacts
[2025-04-20T05:03:06.190+0000] {subprocess.py:93} INFO -     mkdir(artifact_dir)
[2025-04-20T05:03:06.190+0000] {subprocess.py:93} INFO -   File "/home/***/.local/lib/python3.8/site-packages/mlflow/utils/file_utils.py", line 211, in mkdir
[2025-04-20T05:03:06.190+0000] {subprocess.py:93} INFO -     raise e
[2025-04-20T05:03:06.190+0000] {subprocess.py:93} INFO -   File "/home/***/.local/lib/python3.8/site-packages/mlflow/utils/file_utils.py", line 208, in mkdir
[2025-04-20T05:03:06.191+0000] {subprocess.py:93} INFO -     os.makedirs(target, exist_ok=True)
[2025-04-20T05:03:06.191+0000] {subprocess.py:93} INFO -   File "/usr/local/lib/python3.8/os.py", line 213, in makedirs
[2025-04-20T05:03:06.191+0000] {subprocess.py:93} INFO -     makedirs(head, exist_ok=exist_ok)
[2025-04-20T05:03:06.191+0000] {subprocess.py:93} INFO -   File "/usr/local/lib/python3.8/os.py", line 213, in makedirs
[2025-04-20T05:03:06.191+0000] {subprocess.py:93} INFO -     makedirs(head, exist_ok=exist_ok)
[2025-04-20T05:03:06.191+0000] {subprocess.py:93} INFO -   File "/usr/local/lib/python3.8/os.py", line 213, in makedirs
[2025-04-20T05:03:06.191+0000] {subprocess.py:93} INFO -     makedirs(head, exist_ok=exist_ok)
[2025-04-20T05:03:06.192+0000] {subprocess.py:93} INFO -   [Previous line repeated 5 more times]
[2025-04-20T05:03:06.192+0000] {subprocess.py:93} INFO -   File "/usr/local/lib/python3.8/os.py", line 223, in makedirs
[2025-04-20T05:03:06.192+0000] {subprocess.py:93} INFO -     mkdir(name, mode)
[2025-04-20T05:03:06.192+0000] {subprocess.py:93} INFO - PermissionError: [Errno 13] Permission denied: '/Users'
[2025-04-20T05:03:06.445+0000] {subprocess.py:97} INFO - Command exited with return code 1
[2025-04-20T05:03:06.458+0000] {taskinstance.py:1935} ERROR - Task failed with exception
Traceback (most recent call last):
  File "/home/airflow/.local/lib/python3.8/site-packages/airflow/operators/bash.py", line 210, in execute
    raise AirflowException(
airflow.exceptions.AirflowException: Bash command failed. The command returned a non-zero exit code 1.
[2025-04-20T05:03:06.461+0000] {taskinstance.py:1398} INFO - Marking task as FAILED. dag_id=spacex_ml_training_pipeline, task_id=train_model, execution_date=20250413T000000, start_date=20250420T050301, end_date=20250420T050306
[2025-04-20T05:03:06.470+0000] {standard_task_runner.py:104} ERROR - Failed to execute job 4 for task train_model (Bash command failed. The command returned a non-zero exit code 1.; 316)
[2025-04-20T05:03:06.508+0000] {local_task_job_runner.py:228} INFO - Task exited with return code 1
[2025-04-20T05:03:06.520+0000] {taskinstance.py:2776} INFO - 0 downstream tasks scheduled from follow-on schedule check
[2025-04-20T05:13:58.631+0000] {taskinstance.py:1157} INFO - Dependencies all met for dep_context=non-requeueable deps ti=<TaskInstance: spacex_ml_training_pipeline.train_model scheduled__2025-04-13T00:00:00+00:00 [queued]>
[2025-04-20T05:13:58.636+0000] {taskinstance.py:1157} INFO - Dependencies all met for dep_context=requeueable deps ti=<TaskInstance: spacex_ml_training_pipeline.train_model scheduled__2025-04-13T00:00:00+00:00 [queued]>
[2025-04-20T05:13:58.636+0000] {taskinstance.py:1359} INFO - Starting attempt 2 of 2
[2025-04-20T05:13:58.643+0000] {taskinstance.py:1380} INFO - Executing <Task(BashOperator): train_model> on 2025-04-13 00:00:00+00:00
[2025-04-20T05:13:58.646+0000] {standard_task_runner.py:57} INFO - Started process 316 to run task
[2025-04-20T05:13:58.648+0000] {standard_task_runner.py:84} INFO - Running: ['***', 'tasks', 'run', 'spacex_ml_training_pipeline', 'train_model', 'scheduled__2025-04-13T00:00:00+00:00', '--job-id', '4', '--raw', '--subdir', 'DAGS_FOLDER/spacex_training_dag.py', '--cfg-path', '/tmp/tmpvrszu911']
[2025-04-20T05:13:58.650+0000] {standard_task_runner.py:85} INFO - Job 4: Subtask train_model
[2025-04-20T05:13:58.659+0000] {logging_mixin.py:151} WARNING - /home/***/.local/lib/python3.8/site-packages/***/settings.py:195 DeprecationWarning: The sql_alchemy_conn option in [core] has been moved to the sql_alchemy_conn option in [database] - the old setting has been used, but please update your config.
[2025-04-20T05:13:58.679+0000] {task_command.py:415} INFO - Running <TaskInstance: spacex_ml_training_pipeline.train_model scheduled__2025-04-13T00:00:00+00:00 [running]> on host 9446f58958a4
[2025-04-20T05:13:58.721+0000] {taskinstance.py:1660} INFO - Exporting env vars: AIRFLOW_CTX_DAG_OWNER='gaurav' AIRFLOW_CTX_DAG_ID='spacex_ml_training_pipeline' AIRFLOW_CTX_TASK_ID='train_model' AIRFLOW_CTX_EXECUTION_DATE='2025-04-13T00:00:00+00:00' AIRFLOW_CTX_TRY_NUMBER='2' AIRFLOW_CTX_DAG_RUN_ID='scheduled__2025-04-13T00:00:00+00:00'
[2025-04-20T05:13:58.722+0000] {subprocess.py:63} INFO - Tmp dir root location: /tmp
[2025-04-20T05:13:58.723+0000] {subprocess.py:75} INFO - Running command: ['/bin/bash', '-c', 'python /opt/***/project/train.py']
[2025-04-20T05:13:58.732+0000] {subprocess.py:86} INFO - Output:
[2025-04-20T05:14:01.303+0000] {subprocess.py:93} INFO - 2025/04/20 05:14:01 WARNING mlflow.utils.git_utils: Failed to import Git (the Git executable is probably not on your PATH), so Git SHA is not available. Error: Failed to initialize: Bad git executable.
[2025-04-20T05:14:01.304+0000] {subprocess.py:93} INFO - The git executable must be specified in one of the following ways:
[2025-04-20T05:14:01.304+0000] {subprocess.py:93} INFO -     - be included in your $PATH
[2025-04-20T05:14:01.304+0000] {subprocess.py:93} INFO -     - be set via $GIT_PYTHON_GIT_EXECUTABLE
[2025-04-20T05:14:01.305+0000] {subprocess.py:93} INFO -     - explicitly set via git.refresh(<full-path-to-git-executable>)
[2025-04-20T05:14:01.305+0000] {subprocess.py:93} INFO - 
[2025-04-20T05:14:01.305+0000] {subprocess.py:93} INFO - All git commands will error until this is rectified.
[2025-04-20T05:14:01.305+0000] {subprocess.py:93} INFO - 
[2025-04-20T05:14:01.306+0000] {subprocess.py:93} INFO - This initial message can be silenced or aggravated in the future by setting the
[2025-04-20T05:14:01.306+0000] {subprocess.py:93} INFO - $GIT_PYTHON_REFRESH environment variable. Use one of the following values:
[2025-04-20T05:14:01.306+0000] {subprocess.py:93} INFO -     - quiet|q|silence|s|silent|none|n|0: for no message or exception
[2025-04-20T05:14:01.306+0000] {subprocess.py:93} INFO -     - warn|w|warning|log|l|1: for a warning message (logging level CRITICAL, displayed by default)
[2025-04-20T05:14:01.307+0000] {subprocess.py:93} INFO -     - error|e|exception|raise|r|2: for a raised exception
[2025-04-20T05:14:01.307+0000] {subprocess.py:93} INFO - 
[2025-04-20T05:14:01.307+0000] {subprocess.py:93} INFO - Example:
[2025-04-20T05:14:01.307+0000] {subprocess.py:93} INFO -     export GIT_PYTHON_REFRESH=quiet
[2025-04-20T05:14:01.307+0000] {subprocess.py:93} INFO - 
[2025-04-20T05:14:03.505+0000] {subprocess.py:93} INFO - 2025/04/20 05:14:03 WARNING mlflow.models.model: Model logged without a signature and input example. Please set `input_example` parameter when logging the model to auto infer the model signature.
[2025-04-20T05:14:03.521+0000] {subprocess.py:93} INFO - Training LogisticRegression...
[2025-04-20T05:14:03.523+0000] {subprocess.py:93} INFO - Traceback (most recent call last):
[2025-04-20T05:14:03.523+0000] {subprocess.py:93} INFO -   File "/opt/***/project/train.py", line 63, in <module>
[2025-04-20T05:14:03.524+0000] {subprocess.py:93} INFO -     mlflow.sklearn.log_model(clf.best_estimator_, "model")
[2025-04-20T05:14:03.524+0000] {subprocess.py:93} INFO -   File "/home/***/.local/lib/python3.8/site-packages/mlflow/sklearn/__init__.py", line 413, in log_model
[2025-04-20T05:14:03.524+0000] {subprocess.py:93} INFO -     return Model.log(
[2025-04-20T05:14:03.524+0000] {subprocess.py:93} INFO -   File "/home/***/.local/lib/python3.8/site-packages/mlflow/models/model.py", line 744, in log
[2025-04-20T05:14:03.525+0000] {subprocess.py:93} INFO -     mlflow.tracking.fluent.log_artifacts(local_path, mlflow_model.artifact_path, run_id)
[2025-04-20T05:14:03.525+0000] {subprocess.py:93} INFO -   File "/home/***/.local/lib/python3.8/site-packages/mlflow/tracking/fluent.py", line 1170, in log_artifacts
[2025-04-20T05:14:03.525+0000] {subprocess.py:93} INFO -     MlflowClient().log_artifacts(run_id, local_dir, artifact_path)
[2025-04-20T05:14:03.525+0000] {subprocess.py:93} INFO -   File "/home/***/.local/lib/python3.8/site-packages/mlflow/tracking/client.py", line 1977, in log_artifacts
[2025-04-20T05:14:03.525+0000] {subprocess.py:93} INFO -     self._tracking_client.log_artifacts(run_id, local_dir, artifact_path)
[2025-04-20T05:14:03.526+0000] {subprocess.py:93} INFO -   File "/home/***/.local/lib/python3.8/site-packages/mlflow/tracking/_tracking_service/client.py", line 874, in log_artifacts
[2025-04-20T05:14:03.526+0000] {subprocess.py:93} INFO -     self._get_artifact_repo(run_id).log_artifacts(local_dir, artifact_path)
[2025-04-20T05:14:03.526+0000] {subprocess.py:93} INFO -   File "/home/***/.local/lib/python3.8/site-packages/mlflow/store/artifact/local_artifact_repo.py", line 66, in log_artifacts
[2025-04-20T05:14:03.526+0000] {subprocess.py:93} INFO -     mkdir(artifact_dir)
[2025-04-20T05:14:03.526+0000] {subprocess.py:93} INFO -   File "/home/***/.local/lib/python3.8/site-packages/mlflow/utils/file_utils.py", line 211, in mkdir
[2025-04-20T05:14:03.526+0000] {subprocess.py:93} INFO -     raise e
[2025-04-20T05:14:03.526+0000] {subprocess.py:93} INFO -   File "/home/***/.local/lib/python3.8/site-packages/mlflow/utils/file_utils.py", line 208, in mkdir
[2025-04-20T05:14:03.527+0000] {subprocess.py:93} INFO -     os.makedirs(target, exist_ok=True)
[2025-04-20T05:14:03.527+0000] {subprocess.py:93} INFO -   File "/usr/local/lib/python3.8/os.py", line 213, in makedirs
[2025-04-20T05:14:03.527+0000] {subprocess.py:93} INFO -     makedirs(head, exist_ok=exist_ok)
[2025-04-20T05:14:03.527+0000] {subprocess.py:93} INFO -   File "/usr/local/lib/python3.8/os.py", line 213, in makedirs
[2025-04-20T05:14:03.527+0000] {subprocess.py:93} INFO -     makedirs(head, exist_ok=exist_ok)
[2025-04-20T05:14:03.527+0000] {subprocess.py:93} INFO -   File "/usr/local/lib/python3.8/os.py", line 213, in makedirs
[2025-04-20T05:14:03.527+0000] {subprocess.py:93} INFO -     makedirs(head, exist_ok=exist_ok)
[2025-04-20T05:14:03.528+0000] {subprocess.py:93} INFO -   [Previous line repeated 5 more times]
[2025-04-20T05:14:03.528+0000] {subprocess.py:93} INFO -   File "/usr/local/lib/python3.8/os.py", line 223, in makedirs
[2025-04-20T05:14:03.528+0000] {subprocess.py:93} INFO -     mkdir(name, mode)
[2025-04-20T05:14:03.528+0000] {subprocess.py:93} INFO - PermissionError: [Errno 13] Permission denied: '/Users'
[2025-04-20T05:14:03.905+0000] {subprocess.py:97} INFO - Command exited with return code 1
[2025-04-20T05:14:03.926+0000] {taskinstance.py:1935} ERROR - Task failed with exception
Traceback (most recent call last):
  File "/home/airflow/.local/lib/python3.8/site-packages/airflow/operators/bash.py", line 210, in execute
    raise AirflowException(
airflow.exceptions.AirflowException: Bash command failed. The command returned a non-zero exit code 1.
[2025-04-20T05:14:03.931+0000] {taskinstance.py:1398} INFO - Marking task as FAILED. dag_id=spacex_ml_training_pipeline, task_id=train_model, execution_date=20250413T000000, start_date=20250420T051358, end_date=20250420T051403
[2025-04-20T05:14:03.949+0000] {standard_task_runner.py:104} ERROR - Failed to execute job 4 for task train_model (Bash command failed. The command returned a non-zero exit code 1.; 316)
[2025-04-20T05:14:03.969+0000] {local_task_job_runner.py:228} INFO - Task exited with return code 1
[2025-04-20T05:14:03.983+0000] {taskinstance.py:2776} INFO - 0 downstream tasks scheduled from follow-on schedule check
