[2025-04-20T02:03:16.821+0000] {taskinstance.py:1157} INFO - Dependencies all met for dep_context=non-requeueable deps ti=<TaskInstance: spacex_ml_training_pipeline.train_model scheduled__2025-04-13T00:00:00+00:00 [queued]>
[2025-04-20T02:03:16.825+0000] {taskinstance.py:1157} INFO - Dependencies all met for dep_context=requeueable deps ti=<TaskInstance: spacex_ml_training_pipeline.train_model scheduled__2025-04-13T00:00:00+00:00 [queued]>
[2025-04-20T02:03:16.826+0000] {taskinstance.py:1359} INFO - Starting attempt 1 of 2
[2025-04-20T02:03:16.833+0000] {taskinstance.py:1380} INFO - Executing <Task(BashOperator): train_model> on 2025-04-13 00:00:00+00:00
[2025-04-20T02:03:16.837+0000] {standard_task_runner.py:57} INFO - Started process 198 to run task
[2025-04-20T02:03:16.840+0000] {standard_task_runner.py:84} INFO - Running: ['***', 'tasks', 'run', 'spacex_ml_training_pipeline', 'train_model', 'scheduled__2025-04-13T00:00:00+00:00', '--job-id', '2', '--raw', '--subdir', 'DAGS_FOLDER/spacex_training_dag.py', '--cfg-path', '/tmp/tmpmb610zov']
[2025-04-20T02:03:16.841+0000] {standard_task_runner.py:85} INFO - Job 2: Subtask train_model
[2025-04-20T02:03:16.850+0000] {logging_mixin.py:151} WARNING - /home/***/.local/lib/python3.8/site-packages/***/settings.py:195 DeprecationWarning: The sql_alchemy_conn option in [core] has been moved to the sql_alchemy_conn option in [database] - the old setting has been used, but please update your config.
[2025-04-20T02:03:16.871+0000] {task_command.py:415} INFO - Running <TaskInstance: spacex_ml_training_pipeline.train_model scheduled__2025-04-13T00:00:00+00:00 [running]> on host fd4505c3894d
[2025-04-20T02:03:16.914+0000] {taskinstance.py:1660} INFO - Exporting env vars: AIRFLOW_CTX_DAG_OWNER='gaurav' AIRFLOW_CTX_DAG_ID='spacex_ml_training_pipeline' AIRFLOW_CTX_TASK_ID='train_model' AIRFLOW_CTX_EXECUTION_DATE='2025-04-13T00:00:00+00:00' AIRFLOW_CTX_TRY_NUMBER='1' AIRFLOW_CTX_DAG_RUN_ID='scheduled__2025-04-13T00:00:00+00:00'
[2025-04-20T02:03:16.915+0000] {subprocess.py:63} INFO - Tmp dir root location: /tmp
[2025-04-20T02:03:16.916+0000] {subprocess.py:75} INFO - Running command: ['/bin/bash', '-c', 'python /opt/***/project/train.py']
[2025-04-20T02:03:16.921+0000] {subprocess.py:86} INFO - Output:
[2025-04-20T02:03:17.015+0000] {subprocess.py:93} INFO - python: can't open file '/opt/***/project/train.py': [Errno 2] No such file or directory
[2025-04-20T02:03:17.019+0000] {subprocess.py:97} INFO - Command exited with return code 2
[2025-04-20T02:03:17.033+0000] {taskinstance.py:1935} ERROR - Task failed with exception
Traceback (most recent call last):
  File "/home/airflow/.local/lib/python3.8/site-packages/airflow/operators/bash.py", line 210, in execute
    raise AirflowException(
airflow.exceptions.AirflowException: Bash command failed. The command returned a non-zero exit code 2.
[2025-04-20T02:03:17.038+0000] {taskinstance.py:1398} INFO - Marking task as UP_FOR_RETRY. dag_id=spacex_ml_training_pipeline, task_id=train_model, execution_date=20250413T000000, start_date=20250420T020316, end_date=20250420T020317
[2025-04-20T02:03:17.051+0000] {standard_task_runner.py:104} ERROR - Failed to execute job 2 for task train_model (Bash command failed. The command returned a non-zero exit code 2.; 198)
[2025-04-20T02:03:17.064+0000] {local_task_job_runner.py:228} INFO - Task exited with return code 1
[2025-04-20T02:03:17.075+0000] {taskinstance.py:2776} INFO - 0 downstream tasks scheduled from follow-on schedule check
[2025-04-20T02:34:22.578+0000] {taskinstance.py:1157} INFO - Dependencies all met for dep_context=non-requeueable deps ti=<TaskInstance: spacex_ml_training_pipeline.train_model scheduled__2025-04-13T00:00:00+00:00 [queued]>
[2025-04-20T02:34:22.584+0000] {taskinstance.py:1157} INFO - Dependencies all met for dep_context=requeueable deps ti=<TaskInstance: spacex_ml_training_pipeline.train_model scheduled__2025-04-13T00:00:00+00:00 [queued]>
[2025-04-20T02:34:22.584+0000] {taskinstance.py:1359} INFO - Starting attempt 1 of 2
[2025-04-20T02:34:22.593+0000] {taskinstance.py:1380} INFO - Executing <Task(BashOperator): train_model> on 2025-04-13 00:00:00+00:00
[2025-04-20T02:34:22.596+0000] {standard_task_runner.py:57} INFO - Started process 177 to run task
[2025-04-20T02:34:22.599+0000] {standard_task_runner.py:84} INFO - Running: ['***', 'tasks', 'run', 'spacex_ml_training_pipeline', 'train_model', 'scheduled__2025-04-13T00:00:00+00:00', '--job-id', '2', '--raw', '--subdir', 'DAGS_FOLDER/spacex_training_dag.py', '--cfg-path', '/tmp/tmp92o6xg41']
[2025-04-20T02:34:22.601+0000] {standard_task_runner.py:85} INFO - Job 2: Subtask train_model
[2025-04-20T02:34:22.612+0000] {logging_mixin.py:151} WARNING - /home/***/.local/lib/python3.8/site-packages/***/settings.py:195 DeprecationWarning: The sql_alchemy_conn option in [core] has been moved to the sql_alchemy_conn option in [database] - the old setting has been used, but please update your config.
[2025-04-20T02:34:22.634+0000] {task_command.py:415} INFO - Running <TaskInstance: spacex_ml_training_pipeline.train_model scheduled__2025-04-13T00:00:00+00:00 [running]> on host 7d5e8b868ff6
[2025-04-20T02:34:22.682+0000] {taskinstance.py:1660} INFO - Exporting env vars: AIRFLOW_CTX_DAG_OWNER='gaurav' AIRFLOW_CTX_DAG_ID='spacex_ml_training_pipeline' AIRFLOW_CTX_TASK_ID='train_model' AIRFLOW_CTX_EXECUTION_DATE='2025-04-13T00:00:00+00:00' AIRFLOW_CTX_TRY_NUMBER='1' AIRFLOW_CTX_DAG_RUN_ID='scheduled__2025-04-13T00:00:00+00:00'
[2025-04-20T02:34:22.683+0000] {subprocess.py:63} INFO - Tmp dir root location: /tmp
[2025-04-20T02:34:22.683+0000] {subprocess.py:75} INFO - Running command: ['/bin/bash', '-c', 'python /opt/***/project/train.py']
[2025-04-20T02:34:22.688+0000] {subprocess.py:86} INFO - Output:
[2025-04-20T02:34:23.818+0000] {subprocess.py:93} INFO - Traceback (most recent call last):
[2025-04-20T02:34:23.818+0000] {subprocess.py:93} INFO -   File "/opt/***/project/train.py", line 3, in <module>
[2025-04-20T02:34:23.818+0000] {subprocess.py:93} INFO -     from sklearn import preprocessing
[2025-04-20T02:34:23.818+0000] {subprocess.py:93} INFO - ModuleNotFoundError: No module named 'sklearn'
[2025-04-20T02:34:23.855+0000] {subprocess.py:97} INFO - Command exited with return code 1
[2025-04-20T02:34:23.863+0000] {taskinstance.py:1935} ERROR - Task failed with exception
Traceback (most recent call last):
  File "/home/airflow/.local/lib/python3.8/site-packages/airflow/operators/bash.py", line 210, in execute
    raise AirflowException(
airflow.exceptions.AirflowException: Bash command failed. The command returned a non-zero exit code 1.
[2025-04-20T02:34:23.866+0000] {taskinstance.py:1398} INFO - Marking task as UP_FOR_RETRY. dag_id=spacex_ml_training_pipeline, task_id=train_model, execution_date=20250413T000000, start_date=20250420T023422, end_date=20250420T023423
[2025-04-20T02:34:23.873+0000] {standard_task_runner.py:104} ERROR - Failed to execute job 2 for task train_model (Bash command failed. The command returned a non-zero exit code 1.; 177)
[2025-04-20T02:34:23.878+0000] {local_task_job_runner.py:228} INFO - Task exited with return code 1
[2025-04-20T02:34:23.888+0000] {taskinstance.py:2776} INFO - 0 downstream tasks scheduled from follow-on schedule check
[2025-04-20T03:51:44.906+0000] {taskinstance.py:1157} INFO - Dependencies all met for dep_context=non-requeueable deps ti=<TaskInstance: spacex_ml_training_pipeline.train_model scheduled__2025-04-13T00:00:00+00:00 [queued]>
[2025-04-20T03:51:44.911+0000] {taskinstance.py:1157} INFO - Dependencies all met for dep_context=requeueable deps ti=<TaskInstance: spacex_ml_training_pipeline.train_model scheduled__2025-04-13T00:00:00+00:00 [queued]>
[2025-04-20T03:51:44.911+0000] {taskinstance.py:1359} INFO - Starting attempt 1 of 2
[2025-04-20T03:51:44.917+0000] {taskinstance.py:1380} INFO - Executing <Task(BashOperator): train_model> on 2025-04-13 00:00:00+00:00
[2025-04-20T03:51:44.921+0000] {standard_task_runner.py:57} INFO - Started process 183 to run task
[2025-04-20T03:51:44.924+0000] {standard_task_runner.py:84} INFO - Running: ['***', 'tasks', 'run', 'spacex_ml_training_pipeline', 'train_model', 'scheduled__2025-04-13T00:00:00+00:00', '--job-id', '2', '--raw', '--subdir', 'DAGS_FOLDER/spacex_training_dag.py', '--cfg-path', '/tmp/tmp1gu880jl']
[2025-04-20T03:51:44.926+0000] {standard_task_runner.py:85} INFO - Job 2: Subtask train_model
[2025-04-20T03:51:44.935+0000] {logging_mixin.py:151} WARNING - /home/***/.local/lib/python3.8/site-packages/***/settings.py:195 DeprecationWarning: The sql_alchemy_conn option in [core] has been moved to the sql_alchemy_conn option in [database] - the old setting has been used, but please update your config.
[2025-04-20T03:51:44.958+0000] {task_command.py:415} INFO - Running <TaskInstance: spacex_ml_training_pipeline.train_model scheduled__2025-04-13T00:00:00+00:00 [running]> on host 219f96c9b8b2
[2025-04-20T03:51:45.007+0000] {taskinstance.py:1660} INFO - Exporting env vars: AIRFLOW_CTX_DAG_OWNER='gaurav' AIRFLOW_CTX_DAG_ID='spacex_ml_training_pipeline' AIRFLOW_CTX_TASK_ID='train_model' AIRFLOW_CTX_EXECUTION_DATE='2025-04-13T00:00:00+00:00' AIRFLOW_CTX_TRY_NUMBER='1' AIRFLOW_CTX_DAG_RUN_ID='scheduled__2025-04-13T00:00:00+00:00'
[2025-04-20T03:51:45.008+0000] {subprocess.py:63} INFO - Tmp dir root location: /tmp
[2025-04-20T03:51:45.009+0000] {subprocess.py:75} INFO - Running command: ['/bin/bash', '-c', 'python /opt/***/project/train.py']
[2025-04-20T03:51:45.015+0000] {subprocess.py:86} INFO - Output:
[2025-04-20T03:51:48.316+0000] {subprocess.py:93} INFO - 2025/04/20 03:51:48 INFO mlflow.tracking.fluent: Experiment with name 'SpaceX Landing Prediction' does not exist. Creating a new experiment.
[2025-04-20T03:51:48.350+0000] {subprocess.py:93} INFO - 2025/04/20 03:51:48 WARNING mlflow.utils.git_utils: Failed to import Git (the Git executable is probably not on your PATH), so Git SHA is not available. Error: Failed to initialize: Bad git executable.
[2025-04-20T03:51:48.350+0000] {subprocess.py:93} INFO - The git executable must be specified in one of the following ways:
[2025-04-20T03:51:48.350+0000] {subprocess.py:93} INFO -     - be included in your $PATH
[2025-04-20T03:51:48.350+0000] {subprocess.py:93} INFO -     - be set via $GIT_PYTHON_GIT_EXECUTABLE
[2025-04-20T03:51:48.351+0000] {subprocess.py:93} INFO -     - explicitly set via git.refresh(<full-path-to-git-executable>)
[2025-04-20T03:51:48.351+0000] {subprocess.py:93} INFO - 
[2025-04-20T03:51:48.351+0000] {subprocess.py:93} INFO - All git commands will error until this is rectified.
[2025-04-20T03:51:48.351+0000] {subprocess.py:93} INFO - 
[2025-04-20T03:51:48.351+0000] {subprocess.py:93} INFO - This initial message can be silenced or aggravated in the future by setting the
[2025-04-20T03:51:48.351+0000] {subprocess.py:93} INFO - $GIT_PYTHON_REFRESH environment variable. Use one of the following values:
[2025-04-20T03:51:48.351+0000] {subprocess.py:93} INFO -     - quiet|q|silence|s|silent|none|n|0: for no message or exception
[2025-04-20T03:51:48.351+0000] {subprocess.py:93} INFO -     - warn|w|warning|log|l|1: for a warning message (logging level CRITICAL, displayed by default)
[2025-04-20T03:51:48.351+0000] {subprocess.py:93} INFO -     - error|e|exception|raise|r|2: for a raised exception
[2025-04-20T03:51:48.351+0000] {subprocess.py:93} INFO - 
[2025-04-20T03:51:48.352+0000] {subprocess.py:93} INFO - Example:
[2025-04-20T03:51:48.352+0000] {subprocess.py:93} INFO -     export GIT_PYTHON_REFRESH=quiet
[2025-04-20T03:51:48.352+0000] {subprocess.py:93} INFO - 
[2025-04-20T03:51:50.565+0000] {subprocess.py:93} INFO - 2025/04/20 03:51:50 WARNING mlflow.models.model: Model logged without a signature and input example. Please set `input_example` parameter when logging the model to auto infer the model signature.
[2025-04-20T03:51:53.636+0000] {subprocess.py:93} INFO - 2025/04/20 03:51:53 WARNING mlflow.models.model: Model logged without a signature and input example. Please set `input_example` parameter when logging the model to auto infer the model signature.
[2025-04-20T03:51:58.153+0000] {subprocess.py:93} INFO - 2025/04/20 03:51:58 WARNING mlflow.models.model: Model logged without a signature and input example. Please set `input_example` parameter when logging the model to auto infer the model signature.
[2025-04-20T03:52:01.301+0000] {subprocess.py:93} INFO - 2025/04/20 03:52:01 WARNING mlflow.models.model: Model logged without a signature and input example. Please set `input_example` parameter when logging the model to auto infer the model signature.
[2025-04-20T03:52:01.307+0000] {subprocess.py:93} INFO - Training LogisticRegression...
[2025-04-20T03:52:01.307+0000] {subprocess.py:93} INFO - → LogisticRegression logged to MLflow.
[2025-04-20T03:52:01.308+0000] {subprocess.py:93} INFO - Training SVM...
[2025-04-20T03:52:01.308+0000] {subprocess.py:93} INFO - → SVM logged to MLflow.
[2025-04-20T03:52:01.308+0000] {subprocess.py:93} INFO - Training DecisionTree...
[2025-04-20T03:52:01.308+0000] {subprocess.py:93} INFO - → DecisionTree logged to MLflow.
[2025-04-20T03:52:01.308+0000] {subprocess.py:93} INFO - Training KNN...
[2025-04-20T03:52:01.309+0000] {subprocess.py:93} INFO - → KNN logged to MLflow.
[2025-04-20T03:52:01.309+0000] {subprocess.py:93} INFO - Best model saved: DecisionTree
[2025-04-20T03:52:01.702+0000] {subprocess.py:97} INFO - Command exited with return code 0
[2025-04-20T03:52:01.744+0000] {taskinstance.py:1398} INFO - Marking task as SUCCESS. dag_id=spacex_ml_training_pipeline, task_id=train_model, execution_date=20250413T000000, start_date=20250420T035144, end_date=20250420T035201
[2025-04-20T03:52:01.765+0000] {local_task_job_runner.py:228} INFO - Task exited with return code 0
[2025-04-20T03:52:01.785+0000] {taskinstance.py:2776} INFO - 0 downstream tasks scheduled from follow-on schedule check
[2025-04-20T04:24:44.115+0000] {taskinstance.py:1157} INFO - Dependencies all met for dep_context=non-requeueable deps ti=<TaskInstance: spacex_ml_training_pipeline.train_model scheduled__2025-04-13T00:00:00+00:00 [queued]>
[2025-04-20T04:24:44.121+0000] {taskinstance.py:1157} INFO - Dependencies all met for dep_context=requeueable deps ti=<TaskInstance: spacex_ml_training_pipeline.train_model scheduled__2025-04-13T00:00:00+00:00 [queued]>
[2025-04-20T04:24:44.122+0000] {taskinstance.py:1359} INFO - Starting attempt 1 of 2
[2025-04-20T04:24:44.130+0000] {taskinstance.py:1380} INFO - Executing <Task(BashOperator): train_model> on 2025-04-13 00:00:00+00:00
[2025-04-20T04:24:44.133+0000] {standard_task_runner.py:57} INFO - Started process 177 to run task
[2025-04-20T04:24:44.136+0000] {standard_task_runner.py:84} INFO - Running: ['***', 'tasks', 'run', 'spacex_ml_training_pipeline', 'train_model', 'scheduled__2025-04-13T00:00:00+00:00', '--job-id', '2', '--raw', '--subdir', 'DAGS_FOLDER/spacex_training_dag.py', '--cfg-path', '/tmp/tmp9fpnfr69']
[2025-04-20T04:24:44.138+0000] {standard_task_runner.py:85} INFO - Job 2: Subtask train_model
[2025-04-20T04:24:44.148+0000] {logging_mixin.py:151} WARNING - /home/***/.local/lib/python3.8/site-packages/***/settings.py:195 DeprecationWarning: The sql_alchemy_conn option in [core] has been moved to the sql_alchemy_conn option in [database] - the old setting has been used, but please update your config.
[2025-04-20T04:24:44.191+0000] {task_command.py:415} INFO - Running <TaskInstance: spacex_ml_training_pipeline.train_model scheduled__2025-04-13T00:00:00+00:00 [running]> on host 27b3cb63fbb1
[2025-04-20T04:24:44.262+0000] {taskinstance.py:1660} INFO - Exporting env vars: AIRFLOW_CTX_DAG_OWNER='gaurav' AIRFLOW_CTX_DAG_ID='spacex_ml_training_pipeline' AIRFLOW_CTX_TASK_ID='train_model' AIRFLOW_CTX_EXECUTION_DATE='2025-04-13T00:00:00+00:00' AIRFLOW_CTX_TRY_NUMBER='1' AIRFLOW_CTX_DAG_RUN_ID='scheduled__2025-04-13T00:00:00+00:00'
[2025-04-20T04:24:44.264+0000] {subprocess.py:63} INFO - Tmp dir root location: /tmp
[2025-04-20T04:24:44.265+0000] {subprocess.py:75} INFO - Running command: ['/bin/bash', '-c', 'python /opt/***/project/train.py']
[2025-04-20T04:24:44.274+0000] {subprocess.py:86} INFO - Output:
[2025-04-20T04:24:48.001+0000] {subprocess.py:93} INFO - 2025/04/20 04:24:48 INFO mlflow.tracking.fluent: Experiment with name 'SpaceX Landing Prediction' does not exist. Creating a new experiment.
[2025-04-20T04:24:48.030+0000] {subprocess.py:93} INFO - 2025/04/20 04:24:48 WARNING mlflow.utils.git_utils: Failed to import Git (the Git executable is probably not on your PATH), so Git SHA is not available. Error: Failed to initialize: Bad git executable.
[2025-04-20T04:24:48.030+0000] {subprocess.py:93} INFO - The git executable must be specified in one of the following ways:
[2025-04-20T04:24:48.030+0000] {subprocess.py:93} INFO -     - be included in your $PATH
[2025-04-20T04:24:48.030+0000] {subprocess.py:93} INFO -     - be set via $GIT_PYTHON_GIT_EXECUTABLE
[2025-04-20T04:24:48.030+0000] {subprocess.py:93} INFO -     - explicitly set via git.refresh(<full-path-to-git-executable>)
[2025-04-20T04:24:48.031+0000] {subprocess.py:93} INFO - 
[2025-04-20T04:24:48.031+0000] {subprocess.py:93} INFO - All git commands will error until this is rectified.
[2025-04-20T04:24:48.031+0000] {subprocess.py:93} INFO - 
[2025-04-20T04:24:48.031+0000] {subprocess.py:93} INFO - This initial message can be silenced or aggravated in the future by setting the
[2025-04-20T04:24:48.031+0000] {subprocess.py:93} INFO - $GIT_PYTHON_REFRESH environment variable. Use one of the following values:
[2025-04-20T04:24:48.031+0000] {subprocess.py:93} INFO -     - quiet|q|silence|s|silent|none|n|0: for no message or exception
[2025-04-20T04:24:48.031+0000] {subprocess.py:93} INFO -     - warn|w|warning|log|l|1: for a warning message (logging level CRITICAL, displayed by default)
[2025-04-20T04:24:48.032+0000] {subprocess.py:93} INFO -     - error|e|exception|raise|r|2: for a raised exception
[2025-04-20T04:24:48.032+0000] {subprocess.py:93} INFO - 
[2025-04-20T04:24:48.032+0000] {subprocess.py:93} INFO - Example:
[2025-04-20T04:24:48.032+0000] {subprocess.py:93} INFO -     export GIT_PYTHON_REFRESH=quiet
[2025-04-20T04:24:48.032+0000] {subprocess.py:93} INFO - 
[2025-04-20T04:24:50.702+0000] {subprocess.py:93} INFO - 2025/04/20 04:24:50 WARNING mlflow.models.model: Model logged without a signature and input example. Please set `input_example` parameter when logging the model to auto infer the model signature.
[2025-04-20T04:24:53.622+0000] {subprocess.py:93} INFO - 2025/04/20 04:24:53 WARNING mlflow.models.model: Model logged without a signature and input example. Please set `input_example` parameter when logging the model to auto infer the model signature.
[2025-04-20T04:24:57.889+0000] {subprocess.py:93} INFO - 2025/04/20 04:24:57 WARNING mlflow.models.model: Model logged without a signature and input example. Please set `input_example` parameter when logging the model to auto infer the model signature.
[2025-04-20T04:25:00.951+0000] {subprocess.py:93} INFO - 2025/04/20 04:25:00 WARNING mlflow.models.model: Model logged without a signature and input example. Please set `input_example` parameter when logging the model to auto infer the model signature.
[2025-04-20T04:25:00.959+0000] {subprocess.py:93} INFO - Training LogisticRegression...
[2025-04-20T04:25:00.960+0000] {subprocess.py:93} INFO - → LogisticRegression logged to MLflow.
[2025-04-20T04:25:00.960+0000] {subprocess.py:93} INFO - Training SVM...
[2025-04-20T04:25:00.960+0000] {subprocess.py:93} INFO - → SVM logged to MLflow.
[2025-04-20T04:25:00.960+0000] {subprocess.py:93} INFO - Training DecisionTree...
[2025-04-20T04:25:00.961+0000] {subprocess.py:93} INFO - → DecisionTree logged to MLflow.
[2025-04-20T04:25:00.961+0000] {subprocess.py:93} INFO - Training KNN...
[2025-04-20T04:25:00.961+0000] {subprocess.py:93} INFO - → KNN logged to MLflow.
[2025-04-20T04:25:00.961+0000] {subprocess.py:93} INFO - Best model saved: DecisionTree
[2025-04-20T04:25:01.361+0000] {subprocess.py:97} INFO - Command exited with return code 0
[2025-04-20T04:25:01.400+0000] {taskinstance.py:1398} INFO - Marking task as SUCCESS. dag_id=spacex_ml_training_pipeline, task_id=train_model, execution_date=20250413T000000, start_date=20250420T042444, end_date=20250420T042501
[2025-04-20T04:25:01.434+0000] {local_task_job_runner.py:228} INFO - Task exited with return code 0
[2025-04-20T04:25:01.459+0000] {taskinstance.py:2776} INFO - 0 downstream tasks scheduled from follow-on schedule check
[2025-04-20T04:38:07.285+0000] {taskinstance.py:1157} INFO - Dependencies all met for dep_context=non-requeueable deps ti=<TaskInstance: spacex_ml_training_pipeline.train_model scheduled__2025-04-13T00:00:00+00:00 [queued]>
[2025-04-20T04:38:07.299+0000] {taskinstance.py:1157} INFO - Dependencies all met for dep_context=requeueable deps ti=<TaskInstance: spacex_ml_training_pipeline.train_model scheduled__2025-04-13T00:00:00+00:00 [queued]>
[2025-04-20T04:38:07.300+0000] {taskinstance.py:1359} INFO - Starting attempt 1 of 2
[2025-04-20T04:38:07.310+0000] {taskinstance.py:1380} INFO - Executing <Task(BashOperator): train_model> on 2025-04-13 00:00:00+00:00
[2025-04-20T04:38:07.316+0000] {standard_task_runner.py:57} INFO - Started process 183 to run task
[2025-04-20T04:38:07.319+0000] {standard_task_runner.py:84} INFO - Running: ['***', 'tasks', 'run', 'spacex_ml_training_pipeline', 'train_model', 'scheduled__2025-04-13T00:00:00+00:00', '--job-id', '2', '--raw', '--subdir', 'DAGS_FOLDER/spacex_training_dag.py', '--cfg-path', '/tmp/tmpi5c3pjw5']
[2025-04-20T04:38:07.322+0000] {standard_task_runner.py:85} INFO - Job 2: Subtask train_model
[2025-04-20T04:38:07.334+0000] {logging_mixin.py:151} WARNING - /home/***/.local/lib/python3.8/site-packages/***/settings.py:195 DeprecationWarning: The sql_alchemy_conn option in [core] has been moved to the sql_alchemy_conn option in [database] - the old setting has been used, but please update your config.
[2025-04-20T04:38:07.363+0000] {task_command.py:415} INFO - Running <TaskInstance: spacex_ml_training_pipeline.train_model scheduled__2025-04-13T00:00:00+00:00 [running]> on host 86d980d5f4b3
[2025-04-20T04:38:07.417+0000] {taskinstance.py:1660} INFO - Exporting env vars: AIRFLOW_CTX_DAG_OWNER='gaurav' AIRFLOW_CTX_DAG_ID='spacex_ml_training_pipeline' AIRFLOW_CTX_TASK_ID='train_model' AIRFLOW_CTX_EXECUTION_DATE='2025-04-13T00:00:00+00:00' AIRFLOW_CTX_TRY_NUMBER='1' AIRFLOW_CTX_DAG_RUN_ID='scheduled__2025-04-13T00:00:00+00:00'
[2025-04-20T04:38:07.418+0000] {subprocess.py:63} INFO - Tmp dir root location: /tmp
[2025-04-20T04:38:07.418+0000] {subprocess.py:75} INFO - Running command: ['/bin/bash', '-c', 'python /opt/***/project/train.py']
[2025-04-20T04:38:07.425+0000] {subprocess.py:86} INFO - Output:
[2025-04-20T04:38:10.885+0000] {subprocess.py:93} INFO - 2025/04/20 04:38:10 WARNING mlflow.utils.git_utils: Failed to import Git (the Git executable is probably not on your PATH), so Git SHA is not available. Error: Failed to initialize: Bad git executable.
[2025-04-20T04:38:10.887+0000] {subprocess.py:93} INFO - The git executable must be specified in one of the following ways:
[2025-04-20T04:38:10.887+0000] {subprocess.py:93} INFO -     - be included in your $PATH
[2025-04-20T04:38:10.887+0000] {subprocess.py:93} INFO -     - be set via $GIT_PYTHON_GIT_EXECUTABLE
[2025-04-20T04:38:10.887+0000] {subprocess.py:93} INFO -     - explicitly set via git.refresh(<full-path-to-git-executable>)
[2025-04-20T04:38:10.888+0000] {subprocess.py:93} INFO - 
[2025-04-20T04:38:10.888+0000] {subprocess.py:93} INFO - All git commands will error until this is rectified.
[2025-04-20T04:38:10.888+0000] {subprocess.py:93} INFO - 
[2025-04-20T04:38:10.888+0000] {subprocess.py:93} INFO - This initial message can be silenced or aggravated in the future by setting the
[2025-04-20T04:38:10.888+0000] {subprocess.py:93} INFO - $GIT_PYTHON_REFRESH environment variable. Use one of the following values:
[2025-04-20T04:38:10.889+0000] {subprocess.py:93} INFO -     - quiet|q|silence|s|silent|none|n|0: for no message or exception
[2025-04-20T04:38:10.889+0000] {subprocess.py:93} INFO -     - warn|w|warning|log|l|1: for a warning message (logging level CRITICAL, displayed by default)
[2025-04-20T04:38:10.889+0000] {subprocess.py:93} INFO -     - error|e|exception|raise|r|2: for a raised exception
[2025-04-20T04:38:10.889+0000] {subprocess.py:93} INFO - 
[2025-04-20T04:38:10.889+0000] {subprocess.py:93} INFO - Example:
[2025-04-20T04:38:10.890+0000] {subprocess.py:93} INFO -     export GIT_PYTHON_REFRESH=quiet
[2025-04-20T04:38:10.890+0000] {subprocess.py:93} INFO - 
[2025-04-20T04:38:13.079+0000] {subprocess.py:93} INFO - 2025/04/20 04:38:13 WARNING mlflow.models.model: Model logged without a signature and input example. Please set `input_example` parameter when logging the model to auto infer the model signature.
[2025-04-20T04:38:13.092+0000] {subprocess.py:93} INFO - Training LogisticRegression...
[2025-04-20T04:38:13.095+0000] {subprocess.py:93} INFO - Traceback (most recent call last):
[2025-04-20T04:38:13.096+0000] {subprocess.py:93} INFO -   File "/opt/***/project/train.py", line 63, in <module>
[2025-04-20T04:38:13.097+0000] {subprocess.py:93} INFO -     mlflow.sklearn.log_model(clf.best_estimator_, "model")
[2025-04-20T04:38:13.097+0000] {subprocess.py:93} INFO -   File "/home/***/.local/lib/python3.8/site-packages/mlflow/sklearn/__init__.py", line 413, in log_model
[2025-04-20T04:38:13.098+0000] {subprocess.py:93} INFO -     return Model.log(
[2025-04-20T04:38:13.098+0000] {subprocess.py:93} INFO -   File "/home/***/.local/lib/python3.8/site-packages/mlflow/models/model.py", line 744, in log
[2025-04-20T04:38:13.098+0000] {subprocess.py:93} INFO -     mlflow.tracking.fluent.log_artifacts(local_path, mlflow_model.artifact_path, run_id)
[2025-04-20T04:38:13.098+0000] {subprocess.py:93} INFO -   File "/home/***/.local/lib/python3.8/site-packages/mlflow/tracking/fluent.py", line 1170, in log_artifacts
[2025-04-20T04:38:13.098+0000] {subprocess.py:93} INFO -     MlflowClient().log_artifacts(run_id, local_dir, artifact_path)
[2025-04-20T04:38:13.098+0000] {subprocess.py:93} INFO -   File "/home/***/.local/lib/python3.8/site-packages/mlflow/tracking/client.py", line 1977, in log_artifacts
[2025-04-20T04:38:13.100+0000] {subprocess.py:93} INFO -     self._tracking_client.log_artifacts(run_id, local_dir, artifact_path)
[2025-04-20T04:38:13.100+0000] {subprocess.py:93} INFO -   File "/home/***/.local/lib/python3.8/site-packages/mlflow/tracking/_tracking_service/client.py", line 874, in log_artifacts
[2025-04-20T04:38:13.101+0000] {subprocess.py:93} INFO -     self._get_artifact_repo(run_id).log_artifacts(local_dir, artifact_path)
[2025-04-20T04:38:13.101+0000] {subprocess.py:93} INFO -   File "/home/***/.local/lib/python3.8/site-packages/mlflow/store/artifact/local_artifact_repo.py", line 66, in log_artifacts
[2025-04-20T04:38:13.101+0000] {subprocess.py:93} INFO -     mkdir(artifact_dir)
[2025-04-20T04:38:13.101+0000] {subprocess.py:93} INFO -   File "/home/***/.local/lib/python3.8/site-packages/mlflow/utils/file_utils.py", line 211, in mkdir
[2025-04-20T04:38:13.101+0000] {subprocess.py:93} INFO -     raise e
[2025-04-20T04:38:13.101+0000] {subprocess.py:93} INFO -   File "/home/***/.local/lib/python3.8/site-packages/mlflow/utils/file_utils.py", line 208, in mkdir
[2025-04-20T04:38:13.101+0000] {subprocess.py:93} INFO -     os.makedirs(target, exist_ok=True)
[2025-04-20T04:38:13.101+0000] {subprocess.py:93} INFO -   File "/usr/local/lib/python3.8/os.py", line 213, in makedirs
[2025-04-20T04:38:13.101+0000] {subprocess.py:93} INFO -     makedirs(head, exist_ok=exist_ok)
[2025-04-20T04:38:13.101+0000] {subprocess.py:93} INFO -   File "/usr/local/lib/python3.8/os.py", line 213, in makedirs
[2025-04-20T04:38:13.101+0000] {subprocess.py:93} INFO -     makedirs(head, exist_ok=exist_ok)
[2025-04-20T04:38:13.102+0000] {subprocess.py:93} INFO -   File "/usr/local/lib/python3.8/os.py", line 213, in makedirs
[2025-04-20T04:38:13.102+0000] {subprocess.py:93} INFO -     makedirs(head, exist_ok=exist_ok)
[2025-04-20T04:38:13.102+0000] {subprocess.py:93} INFO -   [Previous line repeated 5 more times]
[2025-04-20T04:38:13.102+0000] {subprocess.py:93} INFO -   File "/usr/local/lib/python3.8/os.py", line 223, in makedirs
[2025-04-20T04:38:13.102+0000] {subprocess.py:93} INFO -     mkdir(name, mode)
[2025-04-20T04:38:13.102+0000] {subprocess.py:93} INFO - PermissionError: [Errno 13] Permission denied: '/Users'
[2025-04-20T04:38:13.430+0000] {subprocess.py:97} INFO - Command exited with return code 1
[2025-04-20T04:38:13.440+0000] {taskinstance.py:1935} ERROR - Task failed with exception
Traceback (most recent call last):
  File "/home/airflow/.local/lib/python3.8/site-packages/airflow/operators/bash.py", line 210, in execute
    raise AirflowException(
airflow.exceptions.AirflowException: Bash command failed. The command returned a non-zero exit code 1.
[2025-04-20T04:38:13.443+0000] {taskinstance.py:1398} INFO - Marking task as UP_FOR_RETRY. dag_id=spacex_ml_training_pipeline, task_id=train_model, execution_date=20250413T000000, start_date=20250420T043807, end_date=20250420T043813
[2025-04-20T04:38:13.454+0000] {standard_task_runner.py:104} ERROR - Failed to execute job 2 for task train_model (Bash command failed. The command returned a non-zero exit code 1.; 183)
[2025-04-20T04:38:13.475+0000] {local_task_job_runner.py:228} INFO - Task exited with return code 1
[2025-04-20T04:38:13.493+0000] {taskinstance.py:2776} INFO - 0 downstream tasks scheduled from follow-on schedule check
[2025-04-20T04:57:54.100+0000] {taskinstance.py:1157} INFO - Dependencies all met for dep_context=non-requeueable deps ti=<TaskInstance: spacex_ml_training_pipeline.train_model scheduled__2025-04-13T00:00:00+00:00 [queued]>
[2025-04-20T04:57:54.105+0000] {taskinstance.py:1157} INFO - Dependencies all met for dep_context=requeueable deps ti=<TaskInstance: spacex_ml_training_pipeline.train_model scheduled__2025-04-13T00:00:00+00:00 [queued]>
[2025-04-20T04:57:54.105+0000] {taskinstance.py:1359} INFO - Starting attempt 1 of 2
[2025-04-20T04:57:54.112+0000] {taskinstance.py:1380} INFO - Executing <Task(BashOperator): train_model> on 2025-04-13 00:00:00+00:00
[2025-04-20T04:57:54.116+0000] {standard_task_runner.py:57} INFO - Started process 178 to run task
[2025-04-20T04:57:54.118+0000] {standard_task_runner.py:84} INFO - Running: ['***', 'tasks', 'run', 'spacex_ml_training_pipeline', 'train_model', 'scheduled__2025-04-13T00:00:00+00:00', '--job-id', '2', '--raw', '--subdir', 'DAGS_FOLDER/spacex_training_dag.py', '--cfg-path', '/tmp/tmp5rag3twv']
[2025-04-20T04:57:54.119+0000] {standard_task_runner.py:85} INFO - Job 2: Subtask train_model
[2025-04-20T04:57:54.141+0000] {logging_mixin.py:151} WARNING - /home/***/.local/lib/python3.8/site-packages/***/settings.py:195 DeprecationWarning: The sql_alchemy_conn option in [core] has been moved to the sql_alchemy_conn option in [database] - the old setting has been used, but please update your config.
[2025-04-20T04:57:54.171+0000] {task_command.py:415} INFO - Running <TaskInstance: spacex_ml_training_pipeline.train_model scheduled__2025-04-13T00:00:00+00:00 [running]> on host 8fb4bd7cdd4c
[2025-04-20T04:57:54.220+0000] {taskinstance.py:1660} INFO - Exporting env vars: AIRFLOW_CTX_DAG_OWNER='gaurav' AIRFLOW_CTX_DAG_ID='spacex_ml_training_pipeline' AIRFLOW_CTX_TASK_ID='train_model' AIRFLOW_CTX_EXECUTION_DATE='2025-04-13T00:00:00+00:00' AIRFLOW_CTX_TRY_NUMBER='1' AIRFLOW_CTX_DAG_RUN_ID='scheduled__2025-04-13T00:00:00+00:00'
[2025-04-20T04:57:54.222+0000] {subprocess.py:63} INFO - Tmp dir root location: /tmp
[2025-04-20T04:57:54.222+0000] {subprocess.py:75} INFO - Running command: ['/bin/bash', '-c', 'python /opt/***/project/train.py']
[2025-04-20T04:57:54.228+0000] {subprocess.py:86} INFO - Output:
[2025-04-20T04:57:57.886+0000] {subprocess.py:93} INFO - 2025/04/20 04:57:57 WARNING mlflow.utils.git_utils: Failed to import Git (the Git executable is probably not on your PATH), so Git SHA is not available. Error: Failed to initialize: Bad git executable.
[2025-04-20T04:57:57.887+0000] {subprocess.py:93} INFO - The git executable must be specified in one of the following ways:
[2025-04-20T04:57:57.888+0000] {subprocess.py:93} INFO -     - be included in your $PATH
[2025-04-20T04:57:57.888+0000] {subprocess.py:93} INFO -     - be set via $GIT_PYTHON_GIT_EXECUTABLE
[2025-04-20T04:57:57.888+0000] {subprocess.py:93} INFO -     - explicitly set via git.refresh(<full-path-to-git-executable>)
[2025-04-20T04:57:57.888+0000] {subprocess.py:93} INFO - 
[2025-04-20T04:57:57.888+0000] {subprocess.py:93} INFO - All git commands will error until this is rectified.
[2025-04-20T04:57:57.889+0000] {subprocess.py:93} INFO - 
[2025-04-20T04:57:57.889+0000] {subprocess.py:93} INFO - This initial message can be silenced or aggravated in the future by setting the
[2025-04-20T04:57:57.889+0000] {subprocess.py:93} INFO - $GIT_PYTHON_REFRESH environment variable. Use one of the following values:
[2025-04-20T04:57:57.889+0000] {subprocess.py:93} INFO -     - quiet|q|silence|s|silent|none|n|0: for no message or exception
[2025-04-20T04:57:57.889+0000] {subprocess.py:93} INFO -     - warn|w|warning|log|l|1: for a warning message (logging level CRITICAL, displayed by default)
[2025-04-20T04:57:57.889+0000] {subprocess.py:93} INFO -     - error|e|exception|raise|r|2: for a raised exception
[2025-04-20T04:57:57.890+0000] {subprocess.py:93} INFO - 
[2025-04-20T04:57:57.890+0000] {subprocess.py:93} INFO - Example:
[2025-04-20T04:57:57.890+0000] {subprocess.py:93} INFO -     export GIT_PYTHON_REFRESH=quiet
[2025-04-20T04:57:57.890+0000] {subprocess.py:93} INFO - 
[2025-04-20T04:58:00.690+0000] {subprocess.py:93} INFO - 2025/04/20 04:58:00 WARNING mlflow.models.model: Model logged without a signature and input example. Please set `input_example` parameter when logging the model to auto infer the model signature.
[2025-04-20T04:58:00.710+0000] {subprocess.py:93} INFO - Training LogisticRegression...
[2025-04-20T04:58:00.712+0000] {subprocess.py:93} INFO - Traceback (most recent call last):
[2025-04-20T04:58:00.712+0000] {subprocess.py:93} INFO -   File "/opt/***/project/train.py", line 63, in <module>
[2025-04-20T04:58:00.712+0000] {subprocess.py:93} INFO -     mlflow.sklearn.log_model(clf.best_estimator_, "model")
[2025-04-20T04:58:00.713+0000] {subprocess.py:93} INFO -   File "/home/***/.local/lib/python3.8/site-packages/mlflow/sklearn/__init__.py", line 413, in log_model
[2025-04-20T04:58:00.713+0000] {subprocess.py:93} INFO -     return Model.log(
[2025-04-20T04:58:00.713+0000] {subprocess.py:93} INFO -   File "/home/***/.local/lib/python3.8/site-packages/mlflow/models/model.py", line 744, in log
[2025-04-20T04:58:00.714+0000] {subprocess.py:93} INFO -     mlflow.tracking.fluent.log_artifacts(local_path, mlflow_model.artifact_path, run_id)
[2025-04-20T04:58:00.714+0000] {subprocess.py:93} INFO -   File "/home/***/.local/lib/python3.8/site-packages/mlflow/tracking/fluent.py", line 1170, in log_artifacts
[2025-04-20T04:58:00.714+0000] {subprocess.py:93} INFO -     MlflowClient().log_artifacts(run_id, local_dir, artifact_path)
[2025-04-20T04:58:00.714+0000] {subprocess.py:93} INFO -   File "/home/***/.local/lib/python3.8/site-packages/mlflow/tracking/client.py", line 1977, in log_artifacts
[2025-04-20T04:58:00.714+0000] {subprocess.py:93} INFO -     self._tracking_client.log_artifacts(run_id, local_dir, artifact_path)
[2025-04-20T04:58:00.715+0000] {subprocess.py:93} INFO -   File "/home/***/.local/lib/python3.8/site-packages/mlflow/tracking/_tracking_service/client.py", line 874, in log_artifacts
[2025-04-20T04:58:00.715+0000] {subprocess.py:93} INFO -     self._get_artifact_repo(run_id).log_artifacts(local_dir, artifact_path)
[2025-04-20T04:58:00.715+0000] {subprocess.py:93} INFO -   File "/home/***/.local/lib/python3.8/site-packages/mlflow/store/artifact/local_artifact_repo.py", line 66, in log_artifacts
[2025-04-20T04:58:00.715+0000] {subprocess.py:93} INFO -     mkdir(artifact_dir)
[2025-04-20T04:58:00.715+0000] {subprocess.py:93} INFO -   File "/home/***/.local/lib/python3.8/site-packages/mlflow/utils/file_utils.py", line 211, in mkdir
[2025-04-20T04:58:00.715+0000] {subprocess.py:93} INFO -     raise e
[2025-04-20T04:58:00.716+0000] {subprocess.py:93} INFO -   File "/home/***/.local/lib/python3.8/site-packages/mlflow/utils/file_utils.py", line 208, in mkdir
[2025-04-20T04:58:00.716+0000] {subprocess.py:93} INFO -     os.makedirs(target, exist_ok=True)
[2025-04-20T04:58:00.716+0000] {subprocess.py:93} INFO -   File "/usr/local/lib/python3.8/os.py", line 213, in makedirs
[2025-04-20T04:58:00.716+0000] {subprocess.py:93} INFO -     makedirs(head, exist_ok=exist_ok)
[2025-04-20T04:58:00.717+0000] {subprocess.py:93} INFO -   File "/usr/local/lib/python3.8/os.py", line 213, in makedirs
[2025-04-20T04:58:00.717+0000] {subprocess.py:93} INFO -     makedirs(head, exist_ok=exist_ok)
[2025-04-20T04:58:00.717+0000] {subprocess.py:93} INFO -   File "/usr/local/lib/python3.8/os.py", line 213, in makedirs
[2025-04-20T04:58:00.717+0000] {subprocess.py:93} INFO -     makedirs(head, exist_ok=exist_ok)
[2025-04-20T04:58:00.717+0000] {subprocess.py:93} INFO -   [Previous line repeated 5 more times]
[2025-04-20T04:58:00.717+0000] {subprocess.py:93} INFO -   File "/usr/local/lib/python3.8/os.py", line 223, in makedirs
[2025-04-20T04:58:00.718+0000] {subprocess.py:93} INFO -     mkdir(name, mode)
[2025-04-20T04:58:00.718+0000] {subprocess.py:93} INFO - PermissionError: [Errno 13] Permission denied: '/Users'
[2025-04-20T04:58:00.984+0000] {subprocess.py:97} INFO - Command exited with return code 1
[2025-04-20T04:58:01.004+0000] {taskinstance.py:1935} ERROR - Task failed with exception
Traceback (most recent call last):
  File "/home/airflow/.local/lib/python3.8/site-packages/airflow/operators/bash.py", line 210, in execute
    raise AirflowException(
airflow.exceptions.AirflowException: Bash command failed. The command returned a non-zero exit code 1.
[2025-04-20T04:58:01.008+0000] {taskinstance.py:1398} INFO - Marking task as UP_FOR_RETRY. dag_id=spacex_ml_training_pipeline, task_id=train_model, execution_date=20250413T000000, start_date=20250420T045754, end_date=20250420T045801
[2025-04-20T04:58:01.021+0000] {standard_task_runner.py:104} ERROR - Failed to execute job 2 for task train_model (Bash command failed. The command returned a non-zero exit code 1.; 178)
[2025-04-20T04:58:01.048+0000] {local_task_job_runner.py:228} INFO - Task exited with return code 1
[2025-04-20T04:58:01.069+0000] {taskinstance.py:2776} INFO - 0 downstream tasks scheduled from follow-on schedule check
[2025-04-20T05:08:51.173+0000] {taskinstance.py:1157} INFO - Dependencies all met for dep_context=non-requeueable deps ti=<TaskInstance: spacex_ml_training_pipeline.train_model scheduled__2025-04-13T00:00:00+00:00 [queued]>
[2025-04-20T05:08:51.179+0000] {taskinstance.py:1157} INFO - Dependencies all met for dep_context=requeueable deps ti=<TaskInstance: spacex_ml_training_pipeline.train_model scheduled__2025-04-13T00:00:00+00:00 [queued]>
[2025-04-20T05:08:51.179+0000] {taskinstance.py:1359} INFO - Starting attempt 1 of 2
[2025-04-20T05:08:51.187+0000] {taskinstance.py:1380} INFO - Executing <Task(BashOperator): train_model> on 2025-04-13 00:00:00+00:00
[2025-04-20T05:08:51.191+0000] {standard_task_runner.py:57} INFO - Started process 178 to run task
[2025-04-20T05:08:51.193+0000] {standard_task_runner.py:84} INFO - Running: ['***', 'tasks', 'run', 'spacex_ml_training_pipeline', 'train_model', 'scheduled__2025-04-13T00:00:00+00:00', '--job-id', '2', '--raw', '--subdir', 'DAGS_FOLDER/spacex_training_dag.py', '--cfg-path', '/tmp/tmp17evbz13']
[2025-04-20T05:08:51.195+0000] {standard_task_runner.py:85} INFO - Job 2: Subtask train_model
[2025-04-20T05:08:51.207+0000] {logging_mixin.py:151} WARNING - /home/***/.local/lib/python3.8/site-packages/***/settings.py:195 DeprecationWarning: The sql_alchemy_conn option in [core] has been moved to the sql_alchemy_conn option in [database] - the old setting has been used, but please update your config.
[2025-04-20T05:08:51.232+0000] {task_command.py:415} INFO - Running <TaskInstance: spacex_ml_training_pipeline.train_model scheduled__2025-04-13T00:00:00+00:00 [running]> on host 9446f58958a4
[2025-04-20T05:08:51.279+0000] {taskinstance.py:1660} INFO - Exporting env vars: AIRFLOW_CTX_DAG_OWNER='gaurav' AIRFLOW_CTX_DAG_ID='spacex_ml_training_pipeline' AIRFLOW_CTX_TASK_ID='train_model' AIRFLOW_CTX_EXECUTION_DATE='2025-04-13T00:00:00+00:00' AIRFLOW_CTX_TRY_NUMBER='1' AIRFLOW_CTX_DAG_RUN_ID='scheduled__2025-04-13T00:00:00+00:00'
[2025-04-20T05:08:51.280+0000] {subprocess.py:63} INFO - Tmp dir root location: /tmp
[2025-04-20T05:08:51.281+0000] {subprocess.py:75} INFO - Running command: ['/bin/bash', '-c', 'python /opt/***/project/train.py']
[2025-04-20T05:08:51.287+0000] {subprocess.py:86} INFO - Output:
[2025-04-20T05:08:54.697+0000] {subprocess.py:93} INFO - 2025/04/20 05:08:54 WARNING mlflow.utils.git_utils: Failed to import Git (the Git executable is probably not on your PATH), so Git SHA is not available. Error: Failed to initialize: Bad git executable.
[2025-04-20T05:08:54.697+0000] {subprocess.py:93} INFO - The git executable must be specified in one of the following ways:
[2025-04-20T05:08:54.697+0000] {subprocess.py:93} INFO -     - be included in your $PATH
[2025-04-20T05:08:54.698+0000] {subprocess.py:93} INFO -     - be set via $GIT_PYTHON_GIT_EXECUTABLE
[2025-04-20T05:08:54.698+0000] {subprocess.py:93} INFO -     - explicitly set via git.refresh(<full-path-to-git-executable>)
[2025-04-20T05:08:54.698+0000] {subprocess.py:93} INFO - 
[2025-04-20T05:08:54.698+0000] {subprocess.py:93} INFO - All git commands will error until this is rectified.
[2025-04-20T05:08:54.698+0000] {subprocess.py:93} INFO - 
[2025-04-20T05:08:54.698+0000] {subprocess.py:93} INFO - This initial message can be silenced or aggravated in the future by setting the
[2025-04-20T05:08:54.698+0000] {subprocess.py:93} INFO - $GIT_PYTHON_REFRESH environment variable. Use one of the following values:
[2025-04-20T05:08:54.698+0000] {subprocess.py:93} INFO -     - quiet|q|silence|s|silent|none|n|0: for no message or exception
[2025-04-20T05:08:54.698+0000] {subprocess.py:93} INFO -     - warn|w|warning|log|l|1: for a warning message (logging level CRITICAL, displayed by default)
[2025-04-20T05:08:54.699+0000] {subprocess.py:93} INFO -     - error|e|exception|raise|r|2: for a raised exception
[2025-04-20T05:08:54.699+0000] {subprocess.py:93} INFO - 
[2025-04-20T05:08:54.699+0000] {subprocess.py:93} INFO - Example:
[2025-04-20T05:08:54.699+0000] {subprocess.py:93} INFO -     export GIT_PYTHON_REFRESH=quiet
[2025-04-20T05:08:54.699+0000] {subprocess.py:93} INFO - 
[2025-04-20T05:08:57.147+0000] {subprocess.py:93} INFO - 2025/04/20 05:08:57 WARNING mlflow.models.model: Model logged without a signature and input example. Please set `input_example` parameter when logging the model to auto infer the model signature.
[2025-04-20T05:08:57.164+0000] {subprocess.py:93} INFO - Training LogisticRegression...
[2025-04-20T05:08:57.166+0000] {subprocess.py:93} INFO - Traceback (most recent call last):
[2025-04-20T05:08:57.166+0000] {subprocess.py:93} INFO -   File "/opt/***/project/train.py", line 63, in <module>
[2025-04-20T05:08:57.166+0000] {subprocess.py:93} INFO -     mlflow.sklearn.log_model(clf.best_estimator_, "model")
[2025-04-20T05:08:57.166+0000] {subprocess.py:93} INFO -   File "/home/***/.local/lib/python3.8/site-packages/mlflow/sklearn/__init__.py", line 413, in log_model
[2025-04-20T05:08:57.166+0000] {subprocess.py:93} INFO -     return Model.log(
[2025-04-20T05:08:57.166+0000] {subprocess.py:93} INFO -   File "/home/***/.local/lib/python3.8/site-packages/mlflow/models/model.py", line 744, in log
[2025-04-20T05:08:57.167+0000] {subprocess.py:93} INFO -     mlflow.tracking.fluent.log_artifacts(local_path, mlflow_model.artifact_path, run_id)
[2025-04-20T05:08:57.167+0000] {subprocess.py:93} INFO -   File "/home/***/.local/lib/python3.8/site-packages/mlflow/tracking/fluent.py", line 1170, in log_artifacts
[2025-04-20T05:08:57.167+0000] {subprocess.py:93} INFO -     MlflowClient().log_artifacts(run_id, local_dir, artifact_path)
[2025-04-20T05:08:57.167+0000] {subprocess.py:93} INFO -   File "/home/***/.local/lib/python3.8/site-packages/mlflow/tracking/client.py", line 1977, in log_artifacts
[2025-04-20T05:08:57.167+0000] {subprocess.py:93} INFO -     self._tracking_client.log_artifacts(run_id, local_dir, artifact_path)
[2025-04-20T05:08:57.167+0000] {subprocess.py:93} INFO -   File "/home/***/.local/lib/python3.8/site-packages/mlflow/tracking/_tracking_service/client.py", line 874, in log_artifacts
[2025-04-20T05:08:57.167+0000] {subprocess.py:93} INFO -     self._get_artifact_repo(run_id).log_artifacts(local_dir, artifact_path)
[2025-04-20T05:08:57.168+0000] {subprocess.py:93} INFO -   File "/home/***/.local/lib/python3.8/site-packages/mlflow/store/artifact/local_artifact_repo.py", line 66, in log_artifacts
[2025-04-20T05:08:57.168+0000] {subprocess.py:93} INFO -     mkdir(artifact_dir)
[2025-04-20T05:08:57.168+0000] {subprocess.py:93} INFO -   File "/home/***/.local/lib/python3.8/site-packages/mlflow/utils/file_utils.py", line 211, in mkdir
[2025-04-20T05:08:57.168+0000] {subprocess.py:93} INFO -     raise e
[2025-04-20T05:08:57.168+0000] {subprocess.py:93} INFO -   File "/home/***/.local/lib/python3.8/site-packages/mlflow/utils/file_utils.py", line 208, in mkdir
[2025-04-20T05:08:57.168+0000] {subprocess.py:93} INFO -     os.makedirs(target, exist_ok=True)
[2025-04-20T05:08:57.168+0000] {subprocess.py:93} INFO -   File "/usr/local/lib/python3.8/os.py", line 213, in makedirs
[2025-04-20T05:08:57.168+0000] {subprocess.py:93} INFO -     makedirs(head, exist_ok=exist_ok)
[2025-04-20T05:08:57.168+0000] {subprocess.py:93} INFO -   File "/usr/local/lib/python3.8/os.py", line 213, in makedirs
[2025-04-20T05:08:57.169+0000] {subprocess.py:93} INFO -     makedirs(head, exist_ok=exist_ok)
[2025-04-20T05:08:57.169+0000] {subprocess.py:93} INFO -   File "/usr/local/lib/python3.8/os.py", line 213, in makedirs
[2025-04-20T05:08:57.169+0000] {subprocess.py:93} INFO -     makedirs(head, exist_ok=exist_ok)
[2025-04-20T05:08:57.169+0000] {subprocess.py:93} INFO -   [Previous line repeated 5 more times]
[2025-04-20T05:08:57.169+0000] {subprocess.py:93} INFO -   File "/usr/local/lib/python3.8/os.py", line 223, in makedirs
[2025-04-20T05:08:57.169+0000] {subprocess.py:93} INFO -     mkdir(name, mode)
[2025-04-20T05:08:57.169+0000] {subprocess.py:93} INFO - PermissionError: [Errno 13] Permission denied: '/Users'
[2025-04-20T05:08:57.393+0000] {subprocess.py:97} INFO - Command exited with return code 1
[2025-04-20T05:08:57.403+0000] {taskinstance.py:1935} ERROR - Task failed with exception
Traceback (most recent call last):
  File "/home/airflow/.local/lib/python3.8/site-packages/airflow/operators/bash.py", line 210, in execute
    raise AirflowException(
airflow.exceptions.AirflowException: Bash command failed. The command returned a non-zero exit code 1.
[2025-04-20T05:08:57.406+0000] {taskinstance.py:1398} INFO - Marking task as UP_FOR_RETRY. dag_id=spacex_ml_training_pipeline, task_id=train_model, execution_date=20250413T000000, start_date=20250420T050851, end_date=20250420T050857
[2025-04-20T05:08:57.417+0000] {standard_task_runner.py:104} ERROR - Failed to execute job 2 for task train_model (Bash command failed. The command returned a non-zero exit code 1.; 178)
[2025-04-20T05:08:57.422+0000] {local_task_job_runner.py:228} INFO - Task exited with return code 1
[2025-04-20T05:08:57.436+0000] {taskinstance.py:2776} INFO - 0 downstream tasks scheduled from follow-on schedule check
[2025-04-20T05:17:01.819+0000] {taskinstance.py:1157} INFO - Dependencies all met for dep_context=non-requeueable deps ti=<TaskInstance: spacex_ml_training_pipeline.train_model scheduled__2025-04-13T00:00:00+00:00 [queued]>
[2025-04-20T05:17:01.824+0000] {taskinstance.py:1157} INFO - Dependencies all met for dep_context=requeueable deps ti=<TaskInstance: spacex_ml_training_pipeline.train_model scheduled__2025-04-13T00:00:00+00:00 [queued]>
[2025-04-20T05:17:01.825+0000] {taskinstance.py:1359} INFO - Starting attempt 1 of 2
[2025-04-20T05:17:01.833+0000] {taskinstance.py:1380} INFO - Executing <Task(BashOperator): train_model> on 2025-04-13 00:00:00+00:00
[2025-04-20T05:17:01.838+0000] {standard_task_runner.py:57} INFO - Started process 178 to run task
[2025-04-20T05:17:01.844+0000] {standard_task_runner.py:84} INFO - Running: ['***', 'tasks', 'run', 'spacex_ml_training_pipeline', 'train_model', 'scheduled__2025-04-13T00:00:00+00:00', '--job-id', '2', '--raw', '--subdir', 'DAGS_FOLDER/spacex_training_dag.py', '--cfg-path', '/tmp/tmpds66_jxv']
[2025-04-20T05:17:01.850+0000] {standard_task_runner.py:85} INFO - Job 2: Subtask train_model
[2025-04-20T05:17:01.870+0000] {logging_mixin.py:151} WARNING - /home/***/.local/lib/python3.8/site-packages/***/settings.py:195 DeprecationWarning: The sql_alchemy_conn option in [core] has been moved to the sql_alchemy_conn option in [database] - the old setting has been used, but please update your config.
[2025-04-20T05:17:01.895+0000] {task_command.py:415} INFO - Running <TaskInstance: spacex_ml_training_pipeline.train_model scheduled__2025-04-13T00:00:00+00:00 [running]> on host d19d881c2823
[2025-04-20T05:17:01.967+0000] {taskinstance.py:1660} INFO - Exporting env vars: AIRFLOW_CTX_DAG_OWNER='gaurav' AIRFLOW_CTX_DAG_ID='spacex_ml_training_pipeline' AIRFLOW_CTX_TASK_ID='train_model' AIRFLOW_CTX_EXECUTION_DATE='2025-04-13T00:00:00+00:00' AIRFLOW_CTX_TRY_NUMBER='1' AIRFLOW_CTX_DAG_RUN_ID='scheduled__2025-04-13T00:00:00+00:00'
[2025-04-20T05:17:01.968+0000] {subprocess.py:63} INFO - Tmp dir root location: /tmp
[2025-04-20T05:17:01.969+0000] {subprocess.py:75} INFO - Running command: ['/bin/bash', '-c', 'python /opt/***/project/train.py']
[2025-04-20T05:17:01.974+0000] {subprocess.py:86} INFO - Output:
[2025-04-20T05:17:05.552+0000] {subprocess.py:93} INFO - 2025/04/20 05:17:05 INFO mlflow.tracking.fluent: Experiment with name 'SpaceX Landing Prediction' does not exist. Creating a new experiment.
[2025-04-20T05:17:05.586+0000] {subprocess.py:93} INFO - 2025/04/20 05:17:05 WARNING mlflow.utils.git_utils: Failed to import Git (the Git executable is probably not on your PATH), so Git SHA is not available. Error: Failed to initialize: Bad git executable.
[2025-04-20T05:17:05.586+0000] {subprocess.py:93} INFO - The git executable must be specified in one of the following ways:
[2025-04-20T05:17:05.586+0000] {subprocess.py:93} INFO -     - be included in your $PATH
[2025-04-20T05:17:05.586+0000] {subprocess.py:93} INFO -     - be set via $GIT_PYTHON_GIT_EXECUTABLE
[2025-04-20T05:17:05.586+0000] {subprocess.py:93} INFO -     - explicitly set via git.refresh(<full-path-to-git-executable>)
[2025-04-20T05:17:05.586+0000] {subprocess.py:93} INFO - 
[2025-04-20T05:17:05.587+0000] {subprocess.py:93} INFO - All git commands will error until this is rectified.
[2025-04-20T05:17:05.587+0000] {subprocess.py:93} INFO - 
[2025-04-20T05:17:05.587+0000] {subprocess.py:93} INFO - This initial message can be silenced or aggravated in the future by setting the
[2025-04-20T05:17:05.587+0000] {subprocess.py:93} INFO - $GIT_PYTHON_REFRESH environment variable. Use one of the following values:
[2025-04-20T05:17:05.587+0000] {subprocess.py:93} INFO -     - quiet|q|silence|s|silent|none|n|0: for no message or exception
[2025-04-20T05:17:05.588+0000] {subprocess.py:93} INFO -     - warn|w|warning|log|l|1: for a warning message (logging level CRITICAL, displayed by default)
[2025-04-20T05:17:05.588+0000] {subprocess.py:93} INFO -     - error|e|exception|raise|r|2: for a raised exception
[2025-04-20T05:17:05.588+0000] {subprocess.py:93} INFO - 
[2025-04-20T05:17:05.588+0000] {subprocess.py:93} INFO - Example:
[2025-04-20T05:17:05.588+0000] {subprocess.py:93} INFO -     export GIT_PYTHON_REFRESH=quiet
[2025-04-20T05:17:05.588+0000] {subprocess.py:93} INFO - 
[2025-04-20T05:17:08.058+0000] {subprocess.py:93} INFO - 2025/04/20 05:17:08 WARNING mlflow.models.model: Model logged without a signature and input example. Please set `input_example` parameter when logging the model to auto infer the model signature.
[2025-04-20T05:17:11.154+0000] {subprocess.py:93} INFO - 2025/04/20 05:17:11 WARNING mlflow.models.model: Model logged without a signature and input example. Please set `input_example` parameter when logging the model to auto infer the model signature.
[2025-04-20T05:17:15.871+0000] {subprocess.py:93} INFO - 2025/04/20 05:17:15 WARNING mlflow.models.model: Model logged without a signature and input example. Please set `input_example` parameter when logging the model to auto infer the model signature.
[2025-04-20T05:17:19.161+0000] {subprocess.py:93} INFO - 2025/04/20 05:17:19 WARNING mlflow.models.model: Model logged without a signature and input example. Please set `input_example` parameter when logging the model to auto infer the model signature.
[2025-04-20T05:17:19.254+0000] {subprocess.py:93} INFO - Training LogisticRegression...
[2025-04-20T05:17:19.254+0000] {subprocess.py:93} INFO - → LogisticRegression logged to MLflow.
[2025-04-20T05:17:19.255+0000] {subprocess.py:93} INFO - Training SVM...
[2025-04-20T05:17:19.255+0000] {subprocess.py:93} INFO - → SVM logged to MLflow.
[2025-04-20T05:17:19.255+0000] {subprocess.py:93} INFO - Training DecisionTree...
[2025-04-20T05:17:19.255+0000] {subprocess.py:93} INFO - → DecisionTree logged to MLflow.
[2025-04-20T05:17:19.255+0000] {subprocess.py:93} INFO - Training KNN...
[2025-04-20T05:17:19.255+0000] {subprocess.py:93} INFO - → KNN logged to MLflow.
[2025-04-20T05:17:19.256+0000] {subprocess.py:93} INFO - Best model saved: LogisticRegression
[2025-04-20T05:17:19.636+0000] {subprocess.py:97} INFO - Command exited with return code 0
[2025-04-20T05:17:19.676+0000] {taskinstance.py:1398} INFO - Marking task as SUCCESS. dag_id=spacex_ml_training_pipeline, task_id=train_model, execution_date=20250413T000000, start_date=20250420T051701, end_date=20250420T051719
[2025-04-20T05:17:19.712+0000] {local_task_job_runner.py:228} INFO - Task exited with return code 0
[2025-04-20T05:17:19.737+0000] {taskinstance.py:2776} INFO - 0 downstream tasks scheduled from follow-on schedule check
